Workbook

Sheet 사용법
B1: 왕징양다리양꼬치 매출원가계산서 — 사용법
B2: 한 파일로 1년(1~12월)을 관리합니다. 매일 매출·매입을 쌓고, 매월 말 재고만 세면 원가율이 자동 계산됩니다.
B4: ■ 시트 구성
B5: 월손익요약 | C5: 사장님이 주신 양식(①~⑩) 그대로 계획 vs 실적, 영업이익, 핵심 비율(FL·임대·인건비), 손익분기 매출과 매출 시나리오.
B6: 월손익상세 | C6: ①~⑩ 각 비용의 세부 항목(만원). 계획은 예산, 실적은 그 달 실제 지출 입력. 매출·식재료·의제매입은 자동 연결.
B7: 기본설정 | C7: 상호·연도·조회월·조회지점, 목표 원가율, 분류표, 의제매입 공제율. 매월 [조회월]만 바꾸면 계산서가 그 달로 바뀝니다.
B8: 식자재단가 | C8: 품목 마스터. 거래명세서 단가가 바뀌면 [구매가격]만 수정 → 레시피·메뉴원가·재고금액이 모두 자동 갱신됩니다.
B9: 레시피 | C9: 메뉴 1인분에 들어가는 재료와 사용량(g·ml·개). 품목은 드롭다운으로 선택하세요.
B10: 메뉴원가표 | C10: 메뉴별 1인분 원가·원가율·공헌이익, 월 판매수량 입력 시 이론원가와 메뉴분석(스타/정리검토)까지 표시.
B11: 매출일보 | C11: 매일 마감 후 1줄(지점별). 카드·현금·이체·배달 매출, 그중 주류·음료 매출, 객수 입력.
B12: 매입장 | C12: 거래명세서·영수증 받을 때마다 1줄. 품목을 고르면 분류·단위·과세구분이 자동으로 채워집니다.
B13: 재고실사 | C13: 매월 말일 영업 종료 후 남은 수량을 해당 월 칸에 입력(구매단위 기준: kg, 박스, 병 등).
B14: 매출원가계산서 | C14: 조회월·조회지점의 매출 → 매출원가(분류별) → 원가율 판정 → 매출총이익 → 이론 vs 실제 → 의제매입 참고.
B15: 연간요약 | C15: 1~12월 원가율 추이를 한 표로. 재고실사를 안 한 달은 '미입력'으로 표시됩니다.
B17: ■ 셀 색상 규칙
B18: 노란 바탕 + 파란 글씨 | C18: 직접 입력하는 칸입니다. 여기만 입력하세요.
B19: 흰 바탕 + 검은 글씨 | C19: 자동 계산(수식) 칸입니다. 지우거나 덮어쓰지 마세요.
B20: 초록 글씨 | C20: 다른 시트에서 자동으로 불러온 값입니다.
B22: ■ 운영 루틴
B23: 매일 (3분) | C23: ① 매출일보에 POS 마감 금액 입력 ② 들어온 거래명세서를 매입장에 입력
B24: 매주 (10분) | C24: 식자재단가 시트에서 단가가 오른 품목 확인(변동률 10% 이상은 빨간색). 양고기·주류 단가는 특히 자주 확인.
B25: 매월 말일 (30분) | C25: ① 재고실사 해당 월 칸 입력 ② 기본설정 조회월 변경 ③ 메뉴원가표에 POS 메뉴별 판매수량 입력 ④ 매출원가계산서 확인
B27: ■ 계산 원리
B28: 매출원가 | C28: 기초재고 + 당월매입 − 기말재고 (전월 말 재고 = 이번 달 기초재고, 자동 연결)
B29: 원가율 | C29: 매출원가 ÷ 매출(공급가액, VAT 제외). 식재료는 음식매출과, 주류·음료는 주류매출과 비교합니다.
B30: 이론원가 vs 실제원가 | C30: 이론원가 = 레시피 원가 × 판매수량. 실제원가가 이론보다 5% 이상 크면 로스·과다투입·서비스·도난·매입 오기를 점검하세요.
B31: 금액 기준 | C31: 모든 원가는 공급가액(부가세 제외)으로 계산합니다. 매출도 ÷1.1 해서 공급가액으로 비교합니다.
B33: ■ 왕징 맞춤 관리 포인트
B34: 양고기 | C34: 원가의 가장 큰 비중. 양다리는 해동 손실(수율 95%)을 반영했고, 수율은 실제로 무게를 달아 고치면 더 정확해집니다.
B35: 완제품 꼬치 | C35: 양꼬치는 '박스(100개)' 단위로 매입하고 레시피는 '개' 단위로 사용합니다. 1인분 꼬치 개수가 다르면 레시피에서 수정.
B36: 주류 | C36: 주류는 원가율이 낮은 효자 상품입니다. 음식과 분리해서 보는 이유입니다. 하이볼은 위스키 45ml(연태 30ml) 기준.
B37: 숯·소모품 | C37: 숯은 메뉴별로 나누기 어려워 '소모품' 원가로 따로 집계하고, 계산서에서 포함/제외 원가율을 둘 다 보여줍니다.
B38: 의제매입세액 | C38: 양고기·채소·두부·계란 등 면세 농축수산물 매입은 부가세 신고 때 공제받을 수 있습니다(계산서 6번 참고).
B40: ■ 미리 넣어둔 값에 대해
B41: 단가·레시피 | C41: 식자재 단가와 레시피 사용량은 2026년 도매 시세 기준 '예시 추정치'입니다. 반드시 실제 거래명세서와 주방 계량값으로 바꿔주세요.
B42: 메뉴·판매가 | C42: 홈페이지 메뉴판(44개 메뉴) 가격을 그대로 넣었습니다.
B43: 예시 행 | C43: 매출일보·매입장의 '예시(삭제)' 행은 입력 형식 참고용입니다. 확인 후 행을 지우고 사용하세요.
B44: 지점 | C44: 판교점·모란점이 기본입니다. 기본설정 지점목록에서 이름을 바꾸거나 추가할 수 있습니다.

Sheet 기본설정
B1: 기본설정
B2: 노란 칸만 수정하세요. 매월 [조회월]을 바꾸면 매출원가계산서가 해당 월로 바뀝니다.
B3: 상호 | C3: 왕징양다리양꼬치 | E3: 지점목록 | G3: 분류 | H3: 원가그룹 | I3: 포함 품목 예시 | K3: 사업자 유형 | L3: 공제율 | N3: 과세구분 | O3: 결제방법 | P3: 증빙 | Q3: 원가그룹
B4: 연도 | C4: 2026 | E4: 전체 | G4: 양고기 | H4: 식재료 | I4: 양다리·양갈비·양꼬치(완제품 꼬치 포함)·볶음용 양고기 | K4: 개인(과세표준 2억 이하) | L4: =9/109 -> 0.082568807 | N4: 과세 | O4: 카드 | P4: 세금계산서 | Q4: 식재료
B5: 조회월 (1~12) | C5: 10 | E5: 판교점 | G5: 기타육류 | H5: 식재료 | I5: 돼지고기(꿔바로우·육사용), 닭고기 등 | K5: 개인(과세표준 2억 초과) | L5: =8/108 -> 0.074074074 | N5: 면세 | O5: 계좌이체 | P5: 계산서(면세) | Q5: 주류·음료
B6: 조회지점 | C6: 전체 | E6: 모란점 | G6: 수산물 | H6: 식재료 | I6: 대하·새우꼬치·민물가재(소룽샤) | K6: 법인 | L6: =6/106 -> 0.056603774 | O6: 현금 | P6: 카드전표 | Q6: 소모품
B7: 잡재료 가산율 (양념·기본찬) | C7: 0.05 | G7: 채소·과일 | H7: 식재료 | I7: 가지·토마토·감자·피망·고수·레몬 등 | O7: 외상 | P7: 현금영수증
B8: 목표 식재료 원가율 | C8: 0.35 | G8: 두부·계란·곡류·면 | H8: 식재료 | I8: 두부·건두부·계란·쌀·면류·분모자 | P8: 간이영수증
B9: 목표 주류·음료 원가율 | C9: 0.3 | G9: 냉동·가공식품 | H9: 식재료 | I9: 물만두·꽃빵·피쉬볼 등 완제품
B10: 경고 허용폭 (%p) | C10: 0.03 | G10: 양념·향신료·소스 | H10: 식재료 | I10: 쯔란·마라소스·두반장·춘장·간장·설탕 등
B11: 사업자 유형 (의제매입) | C11: 개인(과세표준 2억 이하) | G11: 유지·기타식재료 | H11: 식재료 | I11: 식용유·참기름·땅콩·기본찬 재료
B12: 의제매입세액 공제율 | C12: =INDEX($L$4:$L$6,MATCH(C11,$K$4:$K$6,0)) -> 0.082568807 | G12: 주류 | H12: 주류·음료 | I12: 백주(연태구냥·설원 등)·맥주·하이볼용 위스키
B13: 이론-실제 허용 차이율 | C13: 0.05 | G13: 음료·얼음 | H13: 주류·음료 | I13: 탄산수·콜라·사이다·얼음
G14: 숯·소모품·포장 | H14: 소모품 | I14: 숯·꼬치·물티슈·앞치마·포장용기
B15: ※ 목표 원가율은 업계 통상치를 참고한 출발값입니다. 3개월 실적을 본 뒤 사장님 기준으로 조정하세요.
B16: ※ 의제매입세액 공제율은 2026년 현행 기준(개인 음식점 과표 2억 이하 9/109 특례). 세법 개정 시 K~L열을 수정하세요.

Sheet 월손익요약
B1: =기본설정!$C$3&" 월 손익 요약" -> 왕징양다리양꼬치 월 손익 요약
B2: ="단위: 만원 | 실적: "&기본설정!$C$4&"년 "&기본설정!$C$5&"월, "&기본설정!$C$6&" | 입력은 [월손익상세] 시트에서" -> 단위: 만원 | 실적: 2026년 10월, 전체 | 입력은 [월손익상세] 시트에서
B4: 항목 | C4: ="계획 (월 "&TEXT(월손익상세!$D$5,"#,##0")&")" -> 계획 (월 5,000) | D4: 매출대비 | E4: 실적 (조회월) | F4: 매출대비 | G4: 차이
B5: 월 매출 (부가세 포함) | C5: =월손익상세!$D$5 -> 5000 | E5: =월손익상세!$F$5 -> 230 | G5: =E5-C5 -> -4770
B6: 인건비 (4대보험 포함) | C6: =월손익상세!$D$36 -> 1300 | D6: =IFERROR(C6/$C$5,0) -> 0.26 | E6: =월손익상세!$F$36 -> 0 | F6: =IFERROR(E6/$E$5,0) -> 0 | G6: =E6-C6 -> -1300
B7: 수도광열·가스·숯 | C7: =월손익상세!$D$43 -> 230 | D7: =IFERROR(C7/$C$5,0) -> 0.046 | E7: =월손익상세!$F$43 -> 0 | F7: =IFERROR(E7/$E$5,0) -> 0 | G7: =E7-C7 -> -230
B8: ① 부가세 실납부 | C8: =월손익상세!$D$13 -> 200.10967 | D8: =IFERROR(C8/$C$5,0) -> 0.040021935 | E8: =월손익상세!$F$13 -> 14.791491 | F8: =IFERROR(E8/$E$5,0) -> 0.06431083 | G8: =E8-C8 -> -185.31818
B9: ② 식재료+주류 | C9: =월손익상세!$D$19 -> 1750 | D9: =IFERROR(C9/$C$5,0) -> 0.35 | E9: =월손익상세!$F$19 -> 70.3 | F9: =IFERROR(E9/$E$5,0) -> 0.30565217 | G9: =E9-C9 -> -1679.7
B10: ③ 카드수수료·소모품 | C10: =월손익상세!$D$30 -> 149.9 | D10: =IFERROR(C10/$C$5,0) -> 0.02998 | E10: =월손익상세!$F$30 -> 2.5254 | F10: =IFERROR(E10/$E$5,0) -> 0.01098 | G10: =E10-C10 -> -147.3746
B11: ④ 인건비 | C11: =월손익상세!$D$36 -> 1300 | D11: =IFERROR(C11/$C$5,0) -> 0.26 | E11: =월손익상세!$F$36 -> 0 | F11: =IFERROR(E11/$E$5,0) -> 0 | G11: =E11-C11 -> -1300
B12: ⑤ 수도광열·가스·숯 | C12: =월손익상세!$D$43 -> 230 | D12: =IFERROR(C12/$C$5,0) -> 0.046 | E12: =월손익상세!$F$43 -> 0 | F12: =IFERROR(E12/$E$5,0) -> 0 | G12: =E12-C12 -> -230
B13: ⑥ 월세 + 부가세 | C13: =월손익상세!$D$49 -> 550 | D13: =IFERROR(C13/$C$5,0) -> 0.11 | E13: =월손익상세!$F$49 -> 0 | F13: =IFERROR(E13/$E$5,0) -> 0 | G13: =E13-C13 -> -550
B14: ⑦ 관리비 | C14: =월손익상세!$D$52 -> 50 | D14: =IFERROR(C14/$C$5,0) -> 0.01 | E14: =월손익상세!$F$52 -> 0 | F14: =IFERROR(E14/$E$5,0) -> 0 | G14: =E14-C14 -> -50
B15: ⑧ 발렛파킹 | C15: =월손익상세!$D$54 -> 100 | D15: =IFERROR(C15/$C$5,0) -> 0.02 | E15: =월손익상세!$F$54 -> 0 | F15: =IFERROR(E15/$E$5,0) -> 0 | G15: =E15-C15 -> -100
B16: ⑨ 마케팅 | C16: =월손익상세!$D$56 -> 500 | D16: =IFERROR(C16/$C$5,0) -> 0.1 | E16: =월손익상세!$F$56 -> 0 | F16: =IFERROR(E16/$E$5,0) -> 0 | G16: =E16-C16 -> -500
B17: ⑩ 기타 고정비 | C17: =월손익상세!$D$63 -> 120 | D17: =IFERROR(C17/$C$5,0) -> 0.024 | E17: =월손익상세!$F$63 -> 0 | F17: =IFERROR(E17/$E$5,0) -> 0 | G17: =E17-C17 -> -120
B18: 총 비용 (①~⑩) | C18: =SUM(C8:C17) -> 4950.0097 | D18: =IFERROR(C18/$C$5,0) -> 0.99000193 | E18: =SUM(E8:E17) -> 87.616891 | F18: =IFERROR(E18/$E$5,0) -> 0.380943 | G18: =SUM(G8:G17) -> -4862.3928
B19: 월 영업이익 (세전) | C19: =C5-C18 -> 49.990325 | D19: =IFERROR(C19/$C$5,0) -> 0.0099980651 | E19: =E5-E18 -> 142.38311 | F19: =IFERROR(E19/$E$5,0) -> 0.619057 | G19: =E19-C19 -> 92.392784
B20: 영업이익률 | C20: =IFERROR(C19/C5,0) -> 0.0099980651 | E20: =IFERROR(E19/E5,0) -> 0.619057 | G20: =E20-C20 -> 0.60905893 | I20: 외식업 평균 5~15%
B21: 임대 관련 비용 비율 (⑥+⑦+⑧) | C21: =IFERROR((C13+C14+C15)/C5,0) -> 0.14 | E21: =IFERROR((E13+E14+E15)/E5,0) -> 0 | G21: =E21-C21 -> -0.14 | I21: 10~15% 이내 권장
B22: 식재료+주류 원가율 (②) | C22: =IFERROR(C9/C5,0) -> 0.35 | E22: =IFERROR(E9/E5,0) -> 0.30565217 | G22: =E22-C22 -> -0.044347826 | I22: 부가세 포함 매출 기준
B23: 인건비율 (④) | C23: =IFERROR(C11/C5,0) -> 0.26 | E23: =IFERROR(E11/E5,0) -> 0 | G23: =E23-C23 -> -0.26 | I23: 25~30% 권장
B24: FL 비율 (식재료+인건비) | C24: =IFERROR((C9+C11)/C5,0) -> 0.61 | E24: =IFERROR((E9+E11)/E5,0) -> 0.30565217 | G24: =E24-C24 -> -0.30434783 | I24: 외식업 핵심 지표, 60~65% 이하 권장
B25: 마케팅비율 (⑨) | C25: =IFERROR(C16/C5,0) -> 0.1 | E25: =IFERROR(E16/E5,0) -> 0 | G25: =E25-C25 -> -0.1 | I25: 3~8% 권장
B27: ■ 손익분기점 · 매출 시나리오 (계획 기준)
B28: 변동비율 (①+②+③) ÷ 매출 | C28: =IFERROR((C8+C9+C10)/C5,0) -> 0.42000193 | D28: 매출이 늘면 같이 늘어나는 비용
B29: 월 고정비 (④~⑩) | C29: =C11+C12+C13+C14+C15+C16+C17 -> 2850 | D29: 매출과 관계없이 나가는 비용
B30: 손익분기 월매출 | C30: =IFERROR(C29/(1-C28),0) -> 4913.8095 | D30: 이 매출을 넘어야 이익이 남습니다
B31: 현재 계획 매출 − 손익분기 | C31: =C5-C30 -> 86.190504 | D31: 여유 매출 (마이너스면 적자 구간)
B32: 하루 손익분기 매출 (월 30일 영업) | C32: =C30/30 -> 163.79365 | D32: 휴무일이 있으면 영업일수로 나눠 보세요
B34: 월 매출 (시나리오) | C34: 변동비 | D34: 고정비 | E34: 영업이익 | F34: 영업이익률
B35: 3000 | C35: =B35*$C$28 -> 1260.0058 | D35: =$C$29 -> 2850 | E35: =B35-C35-D35 -> -1110.0058 | F35: =IFERROR(E35/B35,0) -> -0.37000193
B36: 4000 | C36: =B36*$C$28 -> 1680.0077 | D36: =$C$29 -> 2850 | E36: =B36-C36-D36 -> -530.00774 | F36: =IFERROR(E36/B36,0) -> -0.13250193
B37: 5000 | C37: =B37*$C$28 -> 2100.0097 | D37: =$C$29 -> 2850 | E37: =B37-C37-D37 -> 49.990325 | F37: =IFERROR(E37/B37,0) -> 0.0099980651
B38: 6000 | C38: =B38*$C$28 -> 2520.0116 | D38: =$C$29 -> 2850 | E38: =B38-C38-D38 -> 629.98839 | F38: =IFERROR(E38/B38,0) -> 0.10499807
B39: 7000 | C39: =B39*$C$28 -> 2940.0135 | D39: =$C$29 -> 2850 | E39: =B39-C39-D39 -> 1209.9865 | F39: =IFERROR(E39/B39,0) -> 0.17285521
B41: ※ 시나리오는 계획의 변동비율·고정비를 그대로 적용한 추정입니다. 실제로는 매출이 늘면 아르바이트·전기료도 조금씩 늘어납니다.
B42: ※ 비율은 부가세 포함 매출 대비입니다. 실적 열은 [월손익상세]에 그 달 실제 지출을 입력해야 채워집니다.

Sheet 월손익상세
B1: 월 손익 상세 (단위: 만원)
B2: 노란 칸만 입력. [계획]은 목표 월매출 기준 예산, [실적]은 기본설정 조회월·조회지점 기준(매출·식재료·의제매입은 매출원가계산서에서 자동, 나머지는 통장·카드 내역으로 입력).
B4: ■ 가정 (입력) | D4: 계획 | F4: 실적(조회월)
B5: 월 매출 (부가세 포함) | D5: 5000 | F5: =매출원가계산서!$C$8/10000 -> 230 | I5: 실적은 매출일보 합계에서 자동
B6: 카드결제 비중 | D6: 0.9 | I6: 총매출 중 카드 결제 비율
B7: 카드수수료율 | D7: 0.0122 | I7: 연매출 5~10억 중소가맹점 신용카드 우대수수료 수준(2026). 카드사 안내 문자로 확인
B8: 식재료 중 면세 비중 | D8: 0.6 | I8: 양고기·채소·두부·계란·수산물 등 면세 매입이 식재료(주류·음료 제외)에서 차지하는 비율
B9: 신용카드매출세액공제율 | D9: 0.013 | I9: 개인사업자(연 매출 10억 이하) 카드매출의 1.3%, 연 1,000만원 한도. 법인은 0%로 바꾸세요
B10: 의제매입세액 공제율 | D10: =기본설정!$C$12 -> 0.082568807 | I10: 기본설정에서 자동
B11: ■ 비용 상세
B12: 구분 | C12: 세부항목 | D12: 계획 (만원) | E12: 매출 대비 | F12: 실적 (만원) | G12: 매출 대비 | H12: 차이 (실적−계획) | I12: 기준·메모
B13: ① 부가세 실납부 | C13: 소계 | D13: =D14-D15-D16-D17-D18 -> 200.10967 | E13: =IFERROR(D13/$D$5,0) -> 0.040021935 | F13: =F14-F15-F16-F17-F18 -> 14.791491 | G13: =IF(F13="","",IFERROR(F13/$F$5,0)) -> 0.06431083 | H13: =IF(F13="","",F13-D13) -> -185.31818 | I13: 부가세는 1·7월(개인)에 내지만, 매달 이만큼 따로 떼어 적립하세요
C14: 매출세액 (매출 ÷ 11) | D14: =D5/11 -> 454.54545 | E14: =IFERROR(D14/$D$5,0) -> 0.090909091 | F14: =F5/11 -> 20.909091 | G14: =IF(F14="","",IFERROR(F14/$F$5,0)) -> 0.090909091 | H14: =IF(F14="","",F14-D14) -> -433.63636 | I14: 손님에게 받아둔 부가세
C15: (−) 과세 매입세액 | D15: 85 | E15: =IFERROR(D15/$D$5,0) -> 0.017 | G15: =IF(F15="","",IFERROR(F15/$F$5,0)) | H15: =IF(F15="","",F15-D15) | I15: 식재료·주류·소모품·경비의 세금계산서·카드 매입 부가세. 매입장 '부가세' 열 합계 + 경비 부가세
C16: (−) 의제매입세액 공제 | D16: =(D19-D28-D29)*$D$8*$D$10 -> 60.93578 | E16: =IFERROR(D16/$D$5,0) -> 0.012187156 | F16: =매출원가계산서!$C$55/10000 -> 3.4266 | G16: =IF(F16="","",IFERROR(F16/$F$5,0)) -> 0.014898261 | H16: =IF(F16="","",F16-D16) -> -57.50918 | I16: 면세 식재료 × 공제율. 실적은 매출원가계산서 6번에서 자동
C17: (−) 임대료 부가세 공제 | D17: =D51 -> 50 | E17: =IFERROR(D17/$D$5,0) -> 0.01 | F17: =F51 -> 0 | G17: =IF(F17="","",IFERROR(F17/$F$5,0)) -> 0 | H17: =IF(F17="","",F17-D17) -> -50 | I17: ⑥ 월세 부가세는 세금계산서 받으면 공제
C18: (−) 신용카드매출세액공제 | D18: =MIN(D5*$D$6*$D$9,1000/12) -> 58.5 | E18: =IFERROR(D18/$D$5,0) -> 0.0117 | F18: =MIN(F5*$D$6*$D$9,1000/12) -> 2.691 | G18: =IF(F18="","",IFERROR(F18/$F$5,0)) -> 0.0117 | H18: =IF(F18="","",F18-D18) -> -55.809 | I18: 월 한도 약 83만원(연 1,000만원)
B19: ② 식재료 + 주류 | C19: 소계 | D19: =SUM(D20:D29) -> 1750 | E19: =IFERROR(D19/$D$5,0) -> 0.35 | F19: =SUM(F20:F29) -> 70.3 | G19: =IF(F19="","",IFERROR(F19/$F$5,0)) -> 0.30565217 | H19: =IF(F19="","",F19-D19) -> -1679.7 | I19: 실적은 매출원가계산서(기초재고+매입−기말재고)에서 자동
C20: 양고기 | D20: 650 | E20: =IFERROR(D20/$D$5,0) -> 0.13 | F20: =매출원가계산서!$G$14/10000 -> 41.5 | G20: =IF(F20="","",IFERROR(F20/$F$5,0)) -> 0.18043478 | H20: =IF(F20="","",F20-D20) -> -608.5 | I20: 양다리·양갈비·양꼬치(완제품 꼬치 포함)·볶음용 양고기
C21: 기타육류 | D21: 70 | E21: =IFERROR(D21/$D$5,0) -> 0.014 | F21: =매출원가계산서!$G$15/10000 -> 0 | G21: =IF(F21="","",IFERROR(F21/$F$5,0)) -> 0 | H21: =IF(F21="","",F21-D21) -> -70 | I21: 돼지고기(꿔바로우·육사용), 닭고기 등
C22: 수산물 | D22: 120 | E22: =IFERROR(D22/$D$5,0) -> 0.024 | F22: =매출원가계산서!$G$16/10000 -> 0 | G22: =IF(F22="","",IFERROR(F22/$F$5,0)) -> 0 | H22: =IF(F22="","",F22-D22) -> -120 | I22: 대하·새우꼬치·민물가재(소룽샤)
C23: 채소·과일 | D23: 110 | E23: =IFERROR(D23/$D$5,0) -> 0.022 | F23: =매출원가계산서!$G$17/10000 -> 0 | G23: =IF(F23="","",IFERROR(F23/$F$5,0)) -> 0 | H23: =IF(F23="","",F23-D23) -> -110 | I23: 가지·토마토·감자·피망·고수·레몬 등
C24: 두부·계란·곡류·면 | D24: 80 | E24: =IFERROR(D24/$D$5,0) -> 0.016 | F24: =매출원가계산서!$G$18/10000 -> 0 | G24: =IF(F24="","",IFERROR(F24/$F$5,0)) -> 0 | H24: =IF(F24="","",F24-D24) -> -80 | I24: 두부·건두부·계란·쌀·면류·분모자
C25: 냉동·가공식품 | D25: 50 | E25: =IFERROR(D25/$D$5,0) -> 0.01 | F25: =매출원가계산서!$G$19/10000 -> 0 | G25: =IF(F25="","",IFERROR(F25/$F$5,0)) -> 0 | H25: =IF(F25="","",F25-D25) -> -50 | I25: 물만두·꽃빵·피쉬볼 등 완제품
C26: 양념·향신료·소스 | D26: 90 | E26: =IFERROR(D26/$D$5,0) -> 0.018 | F26: =매출원가계산서!$G$20/10000 -> 0 | G26: =IF(F26="","",IFERROR(F26/$F$5,0)) -> 0 | H26: =IF(F26="","",F26-D26) -> -90 | I26: 쯔란·마라소스·두반장·춘장·간장·설탕 등
C27: 유지·기타식재료 | D27: 60 | E27: =IFERROR(D27/$D$5,0) -> 0.012 | F27: =매출원가계산서!$G$21/10000 -> 0 | G27: =IF(F27="","",IFERROR(F27/$F$5,0)) -> 0 | H27: =IF(F27="","",F27-D27) -> -60 | I27: 식용유·참기름·땅콩·기본찬 재료
C28: 주류 | D28: 450 | E28: =IFERROR(D28/$D$5,0) -> 0.09 | F28: =매출원가계산서!$G$22/10000 -> 28.8 | G28: =IF(F28="","",IFERROR(F28/$F$5,0)) -> 0.12521739 | H28: =IF(F28="","",F28-D28) -> -421.2 | I28: 백주(연태구냥·설원 등)·맥주·하이볼용 위스키
C29: 음료·얼음 | D29: 70 | E29: =IFERROR(D29/$D$5,0) -> 0.014 | F29: =매출원가계산서!$G$23/10000 -> 0 | G29: =IF(F29="","",IFERROR(F29/$F$5,0)) -> 0 | H29: =IF(F29="","",F29-D29) -> -70 | I29: 탄산수·콜라·사이다·얼음
B30: ③ 카드수수료 · 소모품 | C30: 소계 | D30: =SUM(D31:D35) -> 149.9 | E30: =IFERROR(D30/$D$5,0) -> 0.02998 | F30: =SUM(F31:F35) -> 2.5254 | G30: =IF(F30="","",IFERROR(F30/$F$5,0)) -> 0.01098 | H30: =IF(F30="","",F30-D30) -> -147.3746
C31: 카드수수료 | D31: =D5*$D$6*$D$7 -> 54.9 | E31: =IFERROR(D31/$D$5,0) -> 0.01098 | F31: =F5*$D$6*$D$7 -> 2.5254 | G31: =IF(F31="","",IFERROR(F31/$F$5,0)) -> 0.01098 | H31: =IF(F31="","",F31-D31) -> -52.3746 | I31: 매출 × 카드비중 × 수수료율 (자동 추정, 실제 금액으로 덮어써도 됨)
C32: 배달앱 수수료·배달대행비 | D32: 30 | E32: =IFERROR(D32/$D$5,0) -> 0.006 | G32: =IF(F32="","",IFERROR(F32/$F$5,0)) | H32: =IF(F32="","",F32-D32) | I32: 배민·쿠팡이츠 중개수수료 + 배달비 + 결제수수료
C33: 홀 소모품 | D33: 40 | E33: =IFERROR(D33/$D$5,0) -> 0.008 | G33: =IF(F33="","",IFERROR(F33/$F$5,0)) | H33: =IF(F33="","",F33-D33) | I33: 물티슈·냅킨·일회용 앞치마·이쑤시개
C34: 포장용기·비닐 | D34: 10 | E34: =IFERROR(D34/$D$5,0) -> 0.002 | G34: =IF(F34="","",IFERROR(F34/$F$5,0)) | H34: =IF(F34="","",F34-D34) | I34: 포장·배달 용기, 봉투
C35: 주방 소모품 | D35: 15 | E35: =IFERROR(D35/$D$5,0) -> 0.003 | G35: =IF(F35="","",IFERROR(F35/$F$5,0)) | H35: =IF(F35="","",F35-D35) | I35: 세제·랩·호일·위생장갑·수세미
B36: ④ 인건비 (4대보험 포함) | C36: 소계 | D36: =SUM(D37:D42) -> 1300 | E36: =IFERROR(D36/$D$5,0) -> 0.26 | F36: =SUM(F37:F42) -> 0 | G36: =IF(F36="","",IFERROR(F36/$F$5,0)) -> 0 | H36: =IF(F36="","",F36-D36) -> -1300
C37: 주방 직원 급여 | D37: 600 | E37: =IFERROR(D37/$D$5,0) -> 0.12 | G37: =IF(F37="","",IFERROR(F37/$F$5,0)) | H37: =IF(F37="","",F37-D37) | I37: 주방장·주방 보조 (세전 급여)
C38: 홀 직원 급여 | D38: 280 | E38: =IFERROR(D38/$D$5,0) -> 0.056 | G38: =IF(F38="","",IFERROR(F38/$F$5,0)) | H38: =IF(F38="","",F38-D38) | I38: 홀 매니저·정직원
C39: 아르바이트 (주휴·야간수당 포함) | D39: 230 | E39: =IFERROR(D39/$D$5,0) -> 0.046 | G39: =IF(F39="","",IFERROR(F39/$F$5,0)) | H39: =IF(F39="","",F39-D39) | I39: 시급 × 근무시간. 2026 최저시급 이상, 주 15시간 이상은 주휴수당
C40: 4대보험 사업주 부담 | D40: 110 | E40: =IFERROR(D40/$D$5,0) -> 0.022 | G40: =IF(F40="","",IFERROR(F40/$F$5,0)) | H40: =IF(F40="","",F40-D40) | I40: 급여의 약 10~11% (국민·건강·고용·산재)
C41: 퇴직금 적립 | D41: 60 | E41: =IFERROR(D41/$D$5,0) -> 0.012 | G41: =IF(F41="","",IFERROR(F41/$F$5,0)) | H41: =IF(F41="","",F41-D41) | I41: 1년 이상 근무자 월급의 1/12
...

Sheet 매출원가계산서
B1: =기본설정!$C$3&" 매출원가계산서" -> 왕징양다리양꼬치 매출원가계산서
B2: ="기간: "&TEXT($L$2,"yyyy-mm-dd")&" ~ "&TEXT($L$3-1,"yyyy-mm-dd")&" 지점: "&기본설정!$C$6&" (금액 단위: 원, 원가는 부가세 제외 공급가액)" -> 기간: 2026-10-01 ~ 2026-10-31 지점: 전체 (금액 단위: 원, 원가는 부가세 제외 공급가액) | K2: 시작일 | L2: =DATE(기본설정!$C$4,기본설정!$C$5,1) -> 46296
K3: 종료일(미만) | L3: =DATE(기본설정!$C$4,기본설정!$C$5+1,1) -> 46327
B4: 1. 매출 현황
B5: 구분 | C5: 매출 (VAT포함) | D5: 매출 (공급가액) | E5: 구성비
B6: 음식 매출 | C6: =IF(기본설정!$C$6="전체",SUMIFS(매출일보!$I$4:$I$403,매출일보!$A$4:$A$403,">="&$L$2,매출일보!$A$4:$A$403,"<"&$L$3),SUMIFS(매출일보!$I$4:$I$403,매출일보!$A$4:$A$403,">="&$L$2,매출일보!$A$4:$A$403,"<"&$L$3,매출일보!$B$4:$B$403,기본설정!$C$6)) -> 1780000 | D6: =C6/1.1 -> 1618181.8 | E6: =IFERROR(D6/$D$8,0) -> 0.77391304
B7: 주류·음료 매출 | C7: =IF(기본설정!$C$6="전체",SUMIFS(매출일보!$H$4:$H$403,매출일보!$A$4:$A$403,">="&$L$2,매출일보!$A$4:$A$403,"<"&$L$3),SUMIFS(매출일보!$H$4:$H$403,매출일보!$A$4:$A$403,">="&$L$2,매출일보!$A$4:$A$403,"<"&$L$3,매출일보!$B$4:$B$403,기본설정!$C$6)) -> 520000 | D7: =C7/1.1 -> 472727.27 | E7: =IFERROR(D7/$D$8,0) -> 0.22608696
B8: 매출 합계 | C8: =C6+C7 -> 2300000 | D8: =D6+D7 -> 2090909.1 | E8: =IFERROR(D8/$D$8,0) -> 1
B9: 객수 (명) | C9: =IF(기본설정!$C$6="전체",SUMIFS(매출일보!$J$4:$J$403,매출일보!$A$4:$A$403,">="&$L$2,매출일보!$A$4:$A$403,"<"&$L$3),SUMIFS(매출일보!$J$4:$J$403,매출일보!$A$4:$A$403,">="&$L$2,매출일보!$A$4:$A$403,"<"&$L$3,매출일보!$B$4:$B$403,기본설정!$C$6)) -> 62
B10: 객단가 (VAT포함) | C10: =IFERROR(C8/C9,0) -> 37096.774
B12: 2. 매출원가 = 기초재고 + 당월매입 − 기말재고
B13: 분류 | C13: 원가그룹 | D13: 기초재고 | E13: 당월매입 | F13: 기말재고 | G13: 매출원가 | H13: 원가 구성비 | I13: 관련매출 대비
B14: =기본설정!$G$4 -> 양고기 | C14: =기본설정!$H$4 -> 식재료 | D14: =IF(기본설정!$C$6="전체",SUMIFS(재고실사!$V$4:$V$403,재고실사!$B$4:$B$403,$B14),SUMIFS(재고실사!$V$4:$V$403,재고실사!$B$4:$B$403,$B14,재고실사!$A$4:$A$403,기본설정!$C$6)) -> 0 | E14: =IF(기본설정!$C$6="전체",SUMIFS(매입장!$I$4:$I$1503,매입장!$E$4:$E$1503,$B14,매입장!$A$4:$A$1503,">="&$L$2,매입장!$A$4:$A$1503,"<"&$L$3),SUMIFS(매입장!$I$4:$I$1503,매입장!$E$4:$E$1503,$B14,매입장!$A$4:$A$1503,">="&$L$2,매입장!$A$4:$A$1503,"<"&$L$3,매입장!$B$4:$B$1503,기본설정!$C$6)) -> 415000 | F14: =IF(기본설정!$C$6="전체",SUMIFS(재고실사!$T$4:$T$403,재고실사!$B$4:$B$403,$B14),SUMIFS(재고실사!$T$4:$T$403,재고실사!$B$4:$B$403,$B14,재고실사!$A$4:$A$403,기본설정!$C$6)) -> 0 | G14: =D14+E14-F14 -> 415000 | H14: =IFERROR(G14/$G$28,0) -> 0.59032717 | I14: =IFERROR(G14/IF(C14="식재료",$D$6,IF(C14="주류·음료",$D$7,$D$8)),0) -> 0.25646067
B15: =기본설정!$G$5 -> 기타육류 | C15: =기본설정!$H$5 -> 식재료 | D15: =IF(기본설정!$C$6="전체",SUMIFS(재고실사!$V$4:$V$403,재고실사!$B$4:$B$403,$B15),SUMIFS(재고실사!$V$4:$V$403,재고실사!$B$4:$B$403,$B15,재고실사!$A$4:$A$403,기본설정!$C$6)) -> 0 | E15: =IF(기본설정!$C$6="전체",SUMIFS(매입장!$I$4:$I$1503,매입장!$E$4:$E$1503,$B15,매입장!$A$4:$A$1503,">="&$L$2,매입장!$A$4:$A$1503,"<"&$L$3),SUMIFS(매입장!$I$4:$I$1503,매입장!$E$4:$E$1503,$B15,매입장!$A$4:$A$1503,">="&$L$2,매입장!$A$4:$A$1503,"<"&$L$3,매입장!$B$4:$B$1503,기본설정!$C$6)) -> 0 | F15: =IF(기본설정!$C$6="전체",SUMIFS(재고실사!$T$4:$T$403,재고실사!$B$4:$B$403,$B15),SUMIFS(재고실사!$T$4:$T$403,재고실사!$B$4:$B$403,$B15,재고실사!$A$4:$A$403,기본설정!$C$6)) -> 0 | G15: =D15+E15-F15 -> 0 | H15: =IFERROR(G15/$G$28,0) -> 0 | I15: =IFERROR(G15/IF(C15="식재료",$D$6,IF(C15="주류·음료",$D$7,$D$8)),0) -> 0
B16: =기본설정!$G$6 -> 수산물 | C16: =기본설정!$H$6 -> 식재료 | D16: =IF(기본설정!$C$6="전체",SUMIFS(재고실사!$V$4:$V$403,재고실사!$B$4:$B$403,$B16),SUMIFS(재고실사!$V$4:$V$403,재고실사!$B$4:$B$403,$B16,재고실사!$A$4:$A$403,기본설정!$C$6)) -> 0 | E16: =IF(기본설정!$C$6="전체",SUMIFS(매입장!$I$4:$I$1503,매입장!$E$4:$E$1503,$B16,매입장!$A$4:$A$1503,">="&$L$2,매입장!$A$4:$A$1503,"<"&$L$3),SUMIFS(매입장!$I$4:$I$1503,매입장!$E$4:$E$1503,$B16,매입장!$A$4:$A$1503,">="&$L$2,매입장!$A$4:$A$1503,"<"&$L$3,매입장!$B$4:$B$1503,기본설정!$C$6)) -> 0 | F16: =IF(기본설정!$C$6="전체",SUMIFS(재고실사!$T$4:$T$403,재고실사!$B$4:$B$403,$B16),SUMIFS(재고실사!$T$4:$T$403,재고실사!$B$4:$B$403,$B16,재고실사!$A$4:$A$403,기본설정!$C$6)) -> 0 | G16: =D16+E16-F16 -> 0 | H16: =IFERROR(G16/$G$28,0) -> 0 | I16: =IFERROR(G16/IF(C16="식재료",$D$6,IF(C16="주류·음료",$D$7,$D$8)),0) -> 0
B17: =기본설정!$G$7 -> 채소·과일 | C17: =기본설정!$H$7 -> 식재료 | D17: =IF(기본설정!$C$6="전체",SUMIFS(재고실사!$V$4:$V$403,재고실사!$B$4:$B$403,$B17),SUMIFS(재고실사!$V$4:$V$403,재고실사!$B$4:$B$403,$B17,재고실사!$A$4:$A$403,기본설정!$C$6)) -> 0 | E17: =IF(기본설정!$C$6="전체",SUMIFS(매입장!$I$4:$I$1503,매입장!$E$4:$E$1503,$B17,매입장!$A$4:$A$1503,">="&$L$2,매입장!$A$4:$A$1503,"<"&$L$3),SUMIFS(매입장!$I$4:$I$1503,매입장!$E$4:$E$1503,$B17,매입장!$A$4:$A$1503,">="&$L$2,매입장!$A$4:$A$1503,"<"&$L$3,매입장!$B$4:$B$1503,기본설정!$C$6)) -> 0 | F17: =IF(기본설정!$C$6="전체",SUMIFS(재고실사!$T$4:$T$403,재고실사!$B$4:$B$403,$B17),SUMIFS(재고실사!$T$4:$T$403,재고실사!$B$4:$B$403,$B17,재고실사!$A$4:$A$403,기본설정!$C$6)) -> 0 | G17: =D17+E17-F17 -> 0 | H17: =IFERROR(G17/$G$28,0) -> 0 | I17: =IFERROR(G17/IF(C17="식재료",$D$6,IF(C17="주류·음료",$D$7,$D$8)),0) -> 0
B18: =기본설정!$G$8 -> 두부·계란·곡류·면 | C18: =기본설정!$H$8 -> 식재료 | D18: =IF(기본설정!$C$6="전체",SUMIFS(재고실사!$V$4:$V$403,재고실사!$B$4:$B$403,$B18),SUMIFS(재고실사!$V$4:$V$403,재고실사!$B$4:$B$403,$B18,재고실사!$A$4:$A$403,기본설정!$C$6)) -> 0 | E18: =IF(기본설정!$C$6="전체",SUMIFS(매입장!$I$4:$I$1503,매입장!$E$4:$E$1503,$B18,매입장!$A$4:$A$1503,">="&$L$2,매입장!$A$4:$A$1503,"<"&$L$3),SUMIFS(매입장!$I$4:$I$1503,매입장!$E$4:$E$1503,$B18,매입장!$A$4:$A$1503,">="&$L$2,매입장!$A$4:$A$1503,"<"&$L$3,매입장!$B$4:$B$1503,기본설정!$C$6)) -> 0 | F18: =IF(기본설정!$C$6="전체",SUMIFS(재고실사!$T$4:$T$403,재고실사!$B$4:$B$403,$B18),SUMIFS(재고실사!$T$4:$T$403,재고실사!$B$4:$B$403,$B18,재고실사!$A$4:$A$403,기본설정!$C$6)) -> 0 | G18: =D18+E18-F18 -> 0 | H18: =IFERROR(G18/$G$28,0) -> 0 | I18: =IFERROR(G18/IF(C18="식재료",$D$6,IF(C18="주류·음료",$D$7,$D$8)),0) -> 0
B19: =기본설정!$G$9 -> 냉동·가공식품 | C19: =기본설정!$H$9 -> 식재료 | D19: =IF(기본설정!$C$6="전체",SUMIFS(재고실사!$V$4:$V$403,재고실사!$B$4:$B$403,$B19),SUMIFS(재고실사!$V$4:$V$403,재고실사!$B$4:$B$403,$B19,재고실사!$A$4:$A$403,기본설정!$C$6)) -> 0 | E19: =IF(기본설정!$C$6="전체",SUMIFS(매입장!$I$4:$I$1503,매입장!$E$4:$E$1503,$B19,매입장!$A$4:$A$1503,">="&$L$2,매입장!$A$4:$A$1503,"<"&$L$3),SUMIFS(매입장!$I$4:$I$1503,매입장!$E$4:$E$1503,$B19,매입장!$A$4:$A$1503,">="&$L$2,매입장!$A$4:$A$1503,"<"&$L$3,매입장!$B$4:$B$1503,기본설정!$C$6)) -> 0 | F19: =IF(기본설정!$C$6="전체",SUMIFS(재고실사!$T$4:$T$403,재고실사!$B$4:$B$403,$B19),SUMIFS(재고실사!$T$4:$T$403,재고실사!$B$4:$B$403,$B19,재고실사!$A$4:$A$403,기본설정!$C$6)) -> 0 | G19: =D19+E19-F19 -> 0 | H19: =IFERROR(G19/$G$28,0) -> 0 | I19: =IFERROR(G19/IF(C19="식재료",$D$6,IF(C19="주류·음료",$D$7,$D$8)),0) -> 0
B20: =기본설정!$G$10 -> 양념·향신료·소스 | C20: =기본설정!$H$10 -> 식재료 | D20: =IF(기본설정!$C$6="전체",SUMIFS(재고실사!$V$4:$V$403,재고실사!$B$4:$B$403,$B20),SUMIFS(재고실사!$V$4:$V$403,재고실사!$B$4:$B$403,$B20,재고실사!$A$4:$A$403,기본설정!$C$6)) -> 0 | E20: =IF(기본설정!$C$6="전체",SUMIFS(매입장!$I$4:$I$1503,매입장!$E$4:$E$1503,$B20,매입장!$A$4:$A$1503,">="&$L$2,매입장!$A$4:$A$1503,"<"&$L$3),SUMIFS(매입장!$I$4:$I$1503,매입장!$E$4:$E$1503,$B20,매입장!$A$4:$A$1503,">="&$L$2,매입장!$A$4:$A$1503,"<"&$L$3,매입장!$B$4:$B$1503,기본설정!$C$6)) -> 0 | F20: =IF(기본설정!$C$6="전체",SUMIFS(재고실사!$T$4:$T$403,재고실사!$B$4:$B$403,$B20),SUMIFS(재고실사!$T$4:$T$403,재고실사!$B$4:$B$403,$B20,재고실사!$A$4:$A$403,기본설정!$C$6)) -> 0 | G20: =D20+E20-F20 -> 0 | H20: =IFERROR(G20/$G$28,0) -> 0 | I20: =IFERROR(G20/IF(C20="식재료",$D$6,IF(C20="주류·음료",$D$7,$D$8)),0) -> 0
B21: =기본설정!$G$11 -> 유지·기타식재료 | C21: =기본설정!$H$11 -> 식재료 | D21: =IF(기본설정!$C$6="전체",SUMIFS(재고실사!$V$4:$V$403,재고실사!$B$4:$B$403,$B21),SUMIFS(재고실사!$V$4:$V$403,재고실사!$B$4:$B$403,$B21,재고실사!$A$4:$A$403,기본설정!$C$6)) -> 0 | E21: =IF(기본설정!$C$6="전체",SUMIFS(매입장!$I$4:$I$1503,매입장!$E$4:$E$1503,$B21,매입장!$A$4:$A$1503,">="&$L$2,매입장!$A$4:$A$1503,"<"&$L$3),SUMIFS(매입장!$I$4:$I$1503,매입장!$E$4:$E$1503,$B21,매입장!$A$4:$A$1503,">="&$L$2,매입장!$A$4:$A$1503,"<"&$L$3,매입장!$B$4:$B$1503,기본설정!$C$6)) -> 0 | F21: =IF(기본설정!$C$6="전체",SUMIFS(재고실사!$T$4:$T$403,재고실사!$B$4:$B$403,$B21),SUMIFS(재고실사!$T$4:$T$403,재고실사!$B$4:$B$403,$B21,재고실사!$A$4:$A$403,기본설정!$C$6)) -> 0 | G21: =D21+E21-F21 -> 0 | H21: =IFERROR(G21/$G$28,0) -> 0 | I21: =IFERROR(G21/IF(C21="식재료",$D$6,IF(C21="주류·음료",$D$7,$D$8)),0) -> 0
B22: =기본설정!$G$12 -> 주류 | C22: =기본설정!$H$12 -> 주류·음료 | D22: =IF(기본설정!$C$6="전체",SUMIFS(재고실사!$V$4:$V$403,재고실사!$B$4:$B$403,$B22),SUMIFS(재고실사!$V$4:$V$403,재고실사!$B$4:$B$403,$B22,재고실사!$A$4:$A$403,기본설정!$C$6)) -> 0 | E22: =IF(기본설정!$C$6="전체",SUMIFS(매입장!$I$4:$I$1503,매입장!$E$4:$E$1503,$B22,매입장!$A$4:$A$1503,">="&$L$2,매입장!$A$4:$A$1503,"<"&$L$3),SUMIFS(매입장!$I$4:$I$1503,매입장!$E$4:$E$1503,$B22,매입장!$A$4:$A$1503,">="&$L$2,매입장!$A$4:$A$1503,"<"&$L$3,매입장!$B$4:$B$1503,기본설정!$C$6)) -> 288000 | F22: =IF(기본설정!$C$6="전체",SUMIFS(재고실사!$T$4:$T$403,재고실사!$B$4:$B$403,$B22),SUMIFS(재고실사!$T$4:$T$403,재고실사!$B$4:$B$403,$B22,재고실사!$A$4:$A$403,기본설정!$C$6)) -> 0 | G22: =D22+E22-F22 -> 288000 | H22: =IFERROR(G22/$G$28,0) -> 0.40967283 | I22: =IFERROR(G22/IF(C22="식재료",$D$6,IF(C22="주류·음료",$D$7,$D$8)),0) -> 0.60923077
B23: =기본설정!$G$13 -> 음료·얼음 | C23: =기본설정!$H$13 -> 주류·음료 | D23: =IF(기본설정!$C$6="전체",SUMIFS(재고실사!$V$4:$V$403,재고실사!$B$4:$B$403,$B23),SUMIFS(재고실사!$V$4:$V$403,재고실사!$B$4:$B$403,$B23,재고실사!$A$4:$A$403,기본설정!$C$6)) -> 0 | E23: =IF(기본설정!$C$6="전체",SUMIFS(매입장!$I$4:$I$1503,매입장!$E$4:$E$1503,$B23,매입장!$A$4:$A$1503,">="&$L$2,매입장!$A$4:$A$1503,"<"&$L$3),SUMIFS(매입장!$I$4:$I$1503,매입장!$E$4:$E$1503,$B23,매입장!$A$4:$A$1503,">="&$L$2,매입장!$A$4:$A$1503,"<"&$L$3,매입장!$B$4:$B$1503,기본설정!$C$6)) -> 0 | F23: =IF(기본설정!$C$6="전체",SUMIFS(재고실사!$T$4:$T$403,재고실사!$B$4:$B$403,$B23),SUMIFS(재고실사!$T$4:$T$403,재고실사!$B$4:$B$403,$B23,재고실사!$A$4:$A$403,기본설정!$C$6)) -> 0 | G23: =D23+E23-F23 -> 0 | H23: =IFERROR(G23/$G$28,0) -> 0 | I23: =IFERROR(G23/IF(C23="식재료",$D$6,IF(C23="주류·음료",$D$7,$D$8)),0) -> 0
B24: =기본설정!$G$14 -> 숯·소모품·포장 | C24: =기본설정!$H$14 -> 소모품 | D24: =IF(기본설정!$C$6="전체",SUMIFS(재고실사!$V$4:$V$403,재고실사!$B$4:$B$403,$B24),SUMIFS(재고실사!$V$4:$V$403,재고실사!$B$4:$B$403,$B24,재고실사!$A$4:$A$403,기본설정!$C$6)) -> 0 | E24: =IF(기본설정!$C$6="전체",SUMIFS(매입장!$I$4:$I$1503,매입장!$E$4:$E$1503,$B24,매입장!$A$4:$A$1503,">="&$L$2,매입장!$A$4:$A$1503,"<"&$L$3),SUMIFS(매입장!$I$4:$I$1503,매입장!$E$4:$E$1503,$B24,매입장!$A$4:$A$1503,">="&$L$2,매입장!$A$4:$A$1503,"<"&$L$3,매입장!$B$4:$B$1503,기본설정!$C$6)) -> 0 | F24: =IF(기본설정!$C$6="전체",SUMIFS(재고실사!$T$4:$T$403,재고실사!$B$4:$B$403,$B24),SUMIFS(재고실사!$T$4:$T$403,재고실사!$B$4:$B$403,$B24,재고실사!$A$4:$A$403,기본설정!$C$6)) -> 0 | G24: =D24+E24-F24 -> 0 | H24: =IFERROR(G24/$G$28,0) -> 0 | I24: =IFERROR(G24/IF(C24="식재료",$D$6,IF(C24="주류·음료",$D$7,$D$8)),0) -> 0
B25: 식재료 소계 | C25: 식재료 | D25: =SUMIF($C$14:$C$24,$C25,D$14:D$24) -> 0 | E25: =SUMIF($C$14:$C$24,$C25,E$14:E$24) -> 415000 | F25: =SUMIF($C$14:$C$24,$C25,F$14:F$24) -> 0 | G25: =SUMIF($C$14:$C$24,$C25,G$14:G$24) -> 415000 | H25: =IFERROR(G25/$G$28,0) -> 0.59032717 | I25: =IFERROR(G25/$D$6,0) -> 0.25646067
B26: 주류·음료 소계 | C26: 주류·음료 | D26: =SUMIF($C$14:$C$24,$C26,D$14:D$24) -> 0 | E26: =SUMIF($C$14:$C$24,$C26,E$14:E$24) -> 288000 | F26: =SUMIF($C$14:$C$24,$C26,F$14:F$24) -> 0 | G26: =SUMIF($C$14:$C$24,$C26,G$14:G$24) -> 288000 | H26: =IFERROR(G26/$G$28,0) -> 0.40967283 | I26: =IFERROR(G26/$D$7,0) -> 0.60923077
B27: 소모품 소계 | C27: 소모품 | D27: =SUMIF($C$14:$C$24,$C27,D$14:D$24) -> 0 | E27: =SUMIF($C$14:$C$24,$C27,E$14:E$24) -> 0 | F27: =SUMIF($C$14:$C$24,$C27,F$14:F$24) -> 0 | G27: =SUMIF($C$14:$C$24,$C27,G$14:G$24) -> 0 | H27: =IFERROR(G27/$G$28,0) -> 0 | I27: =IFERROR(G27/$D$8,0) -> 0
B28: 매출원가 합계 | D28: =SUM(D25:D27) -> 0 | E28: =SUM(E25:E27) -> 703000 | F28: =SUM(F25:F27) -> 0 | G28: =SUM(G25:G27) -> 703000 | H28: =IFERROR(G28/$G$28,0) -> 1 | I28: =IFERROR(G28/$D$8,0) -> 0.33621739
B29: ※ 기초재고 = 재고실사의 전월말 수량 × 현재 단가, 기말재고 = 조회월말 수량 × 현재 단가. '관련매출 대비'는 식재료→음식매출, 주류·음료→주류매출, 소모품→총매출 기준.
B31: 3. 원가율 분석 (목표 대비)
B32: 구분 | C32: 매출원가 | D32: 매출(공급가) | E32: 실제 원가율 | F32: 목표 원가율 | G32: 차이(%p) | H32: 판정
B33: 식재료 원가율 | C33: =G25 -> 415000 | D33: =D6 -> 1618181.8 | E33: =IFERROR(C33/D33,0) -> 0.25646067 | F33: =기본설정!$C$8 -> 0.35 | G33: =IF(F33="","",E33-F33) -> -0.093539326 | H33: =IF(D33=0,"매출 없음",IF(E33>F33+기본설정!$C$10,"위험",IF(E33>F33,"주의","적정"))) -> 적정
B34: 주류·음료 원가율 | C34: =G26 -> 288000 | D34: =D7 -> 472727.27 | E34: =IFERROR(C34/D34,0) -> 0.60923077 | F34: =기본설정!$C$9 -> 0.3 | G34: =IF(F34="","",E34-F34) -> 0.30923077 | H34: =IF(D34=0,"매출 없음",IF(E34>F34+기본설정!$C$10,"위험",IF(E34>F34,"주의","적정"))) -> 위험
B35: 식재료+주류 원가율 | C35: =G25+G26 -> 703000 | D35: =D8 -> 2090909.1 | E35: =IFERROR(C35/D35,0) -> 0.33621739 | F35: =IFERROR((기본설정!$C$8*D6+기본설정!$C$9*D7)/D8,기본설정!$C$8) -> 0.33869565 | G35: =IF(F35="","",E35-F35) -> -0.0024782609 | H35: =IF(D35=0,"매출 없음",IF(E35>F35+기본설정!$C$10,"위험",IF(E35>F35,"주의","적정"))) -> 적정
B36: 소모품 포함 총원가율 | C36: =G28 -> 703000 | D36: =D8 -> 2090909.1 | E36: =IFERROR(C36/D36,0) -> 0.33621739 | H36: 참고용
B38: 4. 매출총이익
B39: 매출 (공급가액) | C39: =D8 -> 2090909.1
B40: (−) 매출원가 | C40: =G28 -> 703000
B41: 매출총이익 | C41: =C39-C40 -> 1387909.1
B42: 매출총이익률 | C42: =IFERROR(C41/C39,0) -> 0.66378261
B43: 1인당 매출원가 (객수 기준) | C43: =IFERROR(G28/C9,0) -> 11338.71
...

Sheet 연간요약
A1: 연간 요약 (월별 원가율 추이)
A2: 기본설정의 연도·조회지점 기준. 재고실사를 하지 않은 달은 원가가 부정확하니 [재고실사] 열을 확인하세요.
A4: 월 | B4: 총매출 (VAT포함) | C4: 음식매출 (공급가) | D4: 주류매출 (공급가) | E4: 매출 합계 (공급가) | F4: 식재료 매입 | G4: 식재료 원가 | H4: 식재료 원가율 | I4: 주류·음료 매입 | J4: 주류·음료 원가 | K4: 주류 원가율 | L4: 소모품 원가 | M4: 총 매출원가 | N4: 총 원가율 | O4: 매출 총이익 | P4: 총이익률 | Q4: 객수 | R4: 객단가 | S4: 재고실사
A5: 1 | B5: =IF(기본설정!$C$6="전체",SUMIFS(매출일보!$G$4:$G$403,매출일보!$A$4:$A$403,">="&DATE(기본설정!$C$4,$A5,1),매출일보!$A$4:$A$403,"<"&DATE(기본설정!$C$4,$A5+1,1)),SUMIFS(매출일보!$G$4:$G$403,매출일보!$A$4:$A$403,">="&DATE(기본설정!$C$4,$A5,1),매출일보!$A$4:$A$403,"<"&DATE(기본설정!$C$4,$A5+1,1),매출일보!$B$4:$B$403,기본설정!$C$6)) -> 0 | C5: =IF(기본설정!$C$6="전체",SUMIFS(매출일보!$I$4:$I$403,매출일보!$A$4:$A$403,">="&DATE(기본설정!$C$4,$A5,1),매출일보!$A$4:$A$403,"<"&DATE(기본설정!$C$4,$A5+1,1)),SUMIFS(매출일보!$I$4:$I$403,매출일보!$A$4:$A$403,">="&DATE(기본설정!$C$4,$A5,1),매출일보!$A$4:$A$403,"<"&DATE(기본설정!$C$4,$A5+1,1),매출일보!$B$4:$B$403,기본설정!$C$6))/1.1 -> 0 | D5: =IF(기본설정!$C$6="전체",SUMIFS(매출일보!$H$4:$H$403,매출일보!$A$4:$A$403,">="&DATE(기본설정!$C$4,$A5,1),매출일보!$A$4:$A$403,"<"&DATE(기본설정!$C$4,$A5+1,1)),SUMIFS(매출일보!$H$4:$H$403,매출일보!$A$4:$A$403,">="&DATE(기본설정!$C$4,$A5,1),매출일보!$A$4:$A$403,"<"&DATE(기본설정!$C$4,$A5+1,1),매출일보!$B$4:$B$403,기본설정!$C$6))/1.1 -> 0 | E5: =C5+D5 -> 0 | F5: =IF(기본설정!$C$6="전체",SUMIFS(매입장!$I$4:$I$1503,매입장!$P$4:$P$1503,"식재료",매입장!$A$4:$A$1503,">="&DATE(기본설정!$C$4,$A5,1),매입장!$A$4:$A$1503,"<"&DATE(기본설정!$C$4,$A5+1,1)),SUMIFS(매입장!$I$4:$I$1503,매입장!$P$4:$P$1503,"식재료",매입장!$A$4:$A$1503,">="&DATE(기본설정!$C$4,$A5,1),매입장!$A$4:$A$1503,"<"&DATE(기본설정!$C$4,$A5+1,1),매입장!$B$4:$B$1503,기본설정!$C$6)) -> 0 | G5: =IF(기본설정!$C$6="전체",SUMPRODUCT((재고실사!$W$4:$W$403="식재료")*재고실사!$E$4:$E$403*INDEX(재고실사!$F$4:$R$403,0,$A5+0)),SUMPRODUCT((재고실사!$W$4:$W$403="식재료")*(재고실사!$A$4:$A$403=기본설정!$C$6)*재고실사!$E$4:$E$403*INDEX(재고실사!$F$4:$R$403,0,$A5+0)))+IF(기본설정!$C$6="전체",SUMIFS(매입장!$I$4:$I$1503,매입장!$P$4:$P$1503,"식재료",매입장!$A$4:$A$1503,">="&DATE(기본설정!$C$4,$A5,1),매입장!$A$4:$A$1503,"<"&DATE(기본설정!$C$4,$A5+1,1)),SUMIFS(매입장!$I$4:$I$1503,매입장!$P$4:$P$1503,"식재료",매입장!$A$4:$A$1503,">="&DATE(기본설정!$C$4,$A5,1),매입장!$A$4:$A$1503,"<"&DATE(기본설정!$C$4,$A5+1,1),매입장!$B$4:$B$1503,기본설정!$C$6))-IF(기본설정!$C$6="전체",SUMPRODUCT((재고실사!$W$4:$W$403="식재료")*재고실사!$E$4:$E$403*INDEX(재고실사!$F$4:$R$403,0,$A5+1)),SUMPRODUCT((재고실사!$W$4:$W$403="식재료")*(재고실사!$A$4:$A$403=기본설정!$C$6)*재고실사!$E$4:$E$403*INDEX(재고실사!$F$4:$R$403,0,$A5+1))) -> 0 | H5: =IFERROR(G5/C5,0) -> 0 | I5: =IF(기본설정!$C$6="전체",SUMIFS(매입장!$I$4:$I$1503,매입장!$P$4:$P$1503,"주류·음료",매입장!$A$4:$A$1503,">="&DATE(기본설정!$C$4,$A5,1),매입장!$A$4:$A$1503,"<"&DATE(기본설정!$C$4,$A5+1,1)),SUMIFS(매입장!$I$4:$I$1503,매입장!$P$4:$P$1503,"주류·음료",매입장!$A$4:$A$1503,">="&DATE(기본설정!$C$4,$A5,1),매입장!$A$4:$A$1503,"<"&DATE(기본설정!$C$4,$A5+1,1),매입장!$B$4:$B$1503,기본설정!$C$6)) -> 0 | J5: =IF(기본설정!$C$6="전체",SUMPRODUCT((재고실사!$W$4:$W$403="주류·음료")*재고실사!$E$4:$E$403*INDEX(재고실사!$F$4:$R$403,0,$A5+0)),SUMPRODUCT((재고실사!$W$4:$W$403="주류·음료")*(재고실사!$A$4:$A$403=기본설정!$C$6)*재고실사!$E$4:$E$403*INDEX(재고실사!$F$4:$R$403,0,$A5+0)))+IF(기본설정!$C$6="전체",SUMIFS(매입장!$I$4:$I$1503,매입장!$P$4:$P$1503,"주류·음료",매입장!$A$4:$A$1503,">="&DATE(기본설정!$C$4,$A5,1),매입장!$A$4:$A$1503,"<"&DATE(기본설정!$C$4,$A5+1,1)),SUMIFS(매입장!$I$4:$I$1503,매입장!$P$4:$P$1503,"주류·음료",매입장!$A$4:$A$1503,">="&DATE(기본설정!$C$4,$A5,1),매입장!$A$4:$A$1503,"<"&DATE(기본설정!$C$4,$A5+1,1),매입장!$B$4:$B$1503,기본설정!$C$6))-IF(기본설정!$C$6="전체",SUMPRODUCT((재고실사!$W$4:$W$403="주류·음료")*재고실사!$E$4:$E$403*INDEX(재고실사!$F$4:$R$403,0,$A5+1)),SUMPRODUCT((재고실사!$W$4:$W$403="주류·음료")*(재고실사!$A$4:$A$403=기본설정!$C$6)*재고실사!$E$4:$E$403*INDEX(재고실사!$F$4:$R$403,0,$A5+1))) -> 0 | K5: =IFERROR(J5/D5,0) -> 0 | L5: =IF(기본설정!$C$6="전체",SUMPRODUCT((재고실사!$W$4:$W$403="소모품")*재고실사!$E$4:$E$403*INDEX(재고실사!$F$4:$R$403,0,$A5+0)),SUMPRODUCT((재고실사!$W$4:$W$403="소모품")*(재고실사!$A$4:$A$403=기본설정!$C$6)*재고실사!$E$4:$E$403*INDEX(재고실사!$F$4:$R$403,0,$A5+0)))+IF(기본설정!$C$6="전체",SUMIFS(매입장!$I$4:$I$1503,매입장!$P$4:$P$1503,"소모품",매입장!$A$4:$A$1503,">="&DATE(기본설정!$C$4,$A5,1),매입장!$A$4:$A$1503,"<"&DATE(기본설정!$C$4,$A5+1,1)),SUMIFS(매입장!$I$4:$I$1503,매입장!$P$4:$P$1503,"소모품",매입장!$A$4:$A$1503,">="&DATE(기본설정!$C$4,$A5,1),매입장!$A$4:$A$1503,"<"&DATE(기본설정!$C$4,$A5+1,1),매입장!$B$4:$B$1503,기본설정!$C$6))-IF(기본설정!$C$6="전체",SUMPRODUCT((재고실사!$W$4:$W$403="소모품")*재고실사!$E$4:$E$403*INDEX(재고실사!$F$4:$R$403,0,$A5+1)),SUMPRODUCT((재고실사!$W$4:$W$403="소모품")*(재고실사!$A$4:$A$403=기본설정!$C$6)*재고실사!$E$4:$E$403*INDEX(재고실사!$F$4:$R$403,0,$A5+1))) -> 0 | M5: =G5+J5+L5 -> 0 | N5: =IFERROR(M5/E5,0) -> 0 | O5: =E5-M5 -> 0 | P5: =IFERROR(O5/E5,0) -> 0 | Q5: =IF(기본설정!$C$6="전체",SUMIFS(매출일보!$J$4:$J$403,매출일보!$A$4:$A$403,">="&DATE(기본설정!$C$4,$A5,1),매출일보!$A$4:$A$403,"<"&DATE(기본설정!$C$4,$A5+1,1)),SUMIFS(매출일보!$J$4:$J$403,매출일보!$A$4:$A$403,">="&DATE(기본설정!$C$4,$A5,1),매출일보!$A$4:$A$403,"<"&DATE(기본설정!$C$4,$A5+1,1),매출일보!$B$4:$B$403,기본설정!$C$6)) -> 0 | R5: =IFERROR(B5/Q5,0) -> 0 | S5: =IF(SUMPRODUCT(--(INDEX(재고실사!$F$4:$R$403,0,$A5+1)<>""))>0,"입력","미입력") -> 미입력
A6: 2 | B6: =IF(기본설정!$C$6="전체",SUMIFS(매출일보!$G$4:$G$403,매출일보!$A$4:$A$403,">="&DATE(기본설정!$C$4,$A6,1),매출일보!$A$4:$A$403,"<"&DATE(기본설정!$C$4,$A6+1,1)),SUMIFS(매출일보!$G$4:$G$403,매출일보!$A$4:$A$403,">="&DATE(기본설정!$C$4,$A6,1),매출일보!$A$4:$A$403,"<"&DATE(기본설정!$C$4,$A6+1,1),매출일보!$B$4:$B$403,기본설정!$C$6)) -> 0 | C6: =IF(기본설정!$C$6="전체",SUMIFS(매출일보!$I$4:$I$403,매출일보!$A$4:$A$403,">="&DATE(기본설정!$C$4,$A6,1),매출일보!$A$4:$A$403,"<"&DATE(기본설정!$C$4,$A6+1,1)),SUMIFS(매출일보!$I$4:$I$403,매출일보!$A$4:$A$403,">="&DATE(기본설정!$C$4,$A6,1),매출일보!$A$4:$A$403,"<"&DATE(기본설정!$C$4,$A6+1,1),매출일보!$B$4:$B$403,기본설정!$C$6))/1.1 -> 0 | D6: =IF(기본설정!$C$6="전체",SUMIFS(매출일보!$H$4:$H$403,매출일보!$A$4:$A$403,">="&DATE(기본설정!$C$4,$A6,1),매출일보!$A$4:$A$403,"<"&DATE(기본설정!$C$4,$A6+1,1)),SUMIFS(매출일보!$H$4:$H$403,매출일보!$A$4:$A$403,">="&DATE(기본설정!$C$4,$A6,1),매출일보!$A$4:$A$403,"<"&DATE(기본설정!$C$4,$A6+1,1),매출일보!$B$4:$B$403,기본설정!$C$6))/1.1 -> 0 | E6: =C6+D6 -> 0 | F6: =IF(기본설정!$C$6="전체",SUMIFS(매입장!$I$4:$I$1503,매입장!$P$4:$P$1503,"식재료",매입장!$A$4:$A$1503,">="&DATE(기본설정!$C$4,$A6,1),매입장!$A$4:$A$1503,"<"&DATE(기본설정!$C$4,$A6+1,1)),SUMIFS(매입장!$I$4:$I$1503,매입장!$P$4:$P$1503,"식재료",매입장!$A$4:$A$1503,">="&DATE(기본설정!$C$4,$A6,1),매입장!$A$4:$A$1503,"<"&DATE(기본설정!$C$4,$A6+1,1),매입장!$B$4:$B$1503,기본설정!$C$6)) -> 0 | G6: =IF(기본설정!$C$6="전체",SUMPRODUCT((재고실사!$W$4:$W$403="식재료")*재고실사!$E$4:$E$403*INDEX(재고실사!$F$4:$R$403,0,$A6+0)),SUMPRODUCT((재고실사!$W$4:$W$403="식재료")*(재고실사!$A$4:$A$403=기본설정!$C$6)*재고실사!$E$4:$E$403*INDEX(재고실사!$F$4:$R$403,0,$A6+0)))+IF(기본설정!$C$6="전체",SUMIFS(매입장!$I$4:$I$1503,매입장!$P$4:$P$1503,"식재료",매입장!$A$4:$A$1503,">="&DATE(기본설정!$C$4,$A6,1),매입장!$A$4:$A$1503,"<"&DATE(기본설정!$C$4,$A6+1,1)),SUMIFS(매입장!$I$4:$I$1503,매입장!$P$4:$P$1503,"식재료",매입장!$A$4:$A$1503,">="&DATE(기본설정!$C$4,$A6,1),매입장!$A$4:$A$1503,"<"&DATE(기본설정!$C$4,$A6+1,1),매입장!$B$4:$B$1503,기본설정!$C$6))-IF(기본설정!$C$6="전체",SUMPRODUCT((재고실사!$W$4:$W$403="식재료")*재고실사!$E$4:$E$403*INDEX(재고실사!$F$4:$R$403,0,$A6+1)),SUMPRODUCT((재고실사!$W$4:$W$403="식재료")*(재고실사!$A$4:$A$403=기본설정!$C$6)*재고실사!$E$4:$E$403*INDEX(재고실사!$F$4:$R$403,0,$A6+1))) -> 0 | H6: =IFERROR(G6/C6,0) -> 0 | I6: =IF(기본설정!$C$6="전체",SUMIFS(매입장!$I$4:$I$1503,매입장!$P$4:$P$1503,"주류·음료",매입장!$A$4:$A$1503,">="&DATE(기본설정!$C$4,$A6,1),매입장!$A$4:$A$1503,"<"&DATE(기본설정!$C$4,$A6+1,1)),SUMIFS(매입장!$I$4:$I$1503,매입장!$P$4:$P$1503,"주류·음료",매입장!$A$4:$A$1503,">="&DATE(기본설정!$C$4,$A6,1),매입장!$A$4:$A$1503,"<"&DATE(기본설정!$C$4,$A6+1,1),매입장!$B$4:$B$1503,기본설정!$C$6)) -> 0 | J6: =IF(기본설정!$C$6="전체",SUMPRODUCT((재고실사!$W$4:$W$403="주류·음료")*재고실사!$E$4:$E$403*INDEX(재고실사!$F$4:$R$403,0,$A6+0)),SUMPRODUCT((재고실사!$W$4:$W$403="주류·음료")*(재고실사!$A$4:$A$403=기본설정!$C$6)*재고실사!$E$4:$E$403*INDEX(재고실사!$F$4:$R$403,0,$A6+0)))+IF(기본설정!$C$6="전체",SUMIFS(매입장!$I$4:$I$1503,매입장!$P$4:$P$1503,"주류·음료",매입장!$A$4:$A$1503,">="&DATE(기본설정!$C$4,$A6,1),매입장!$A$4:$A$1503,"<"&DATE(기본설정!$C$4,$A6+1,1)),SUMIFS(매입장!$I$4:$I$1503,매입장!$P$4:$P$1503,"주류·음료",매입장!$A$4:$A$1503,">="&DATE(기본설정!$C$4,$A6,1),매입장!$A$4:$A$1503,"<"&DATE(기본설정!$C$4,$A6+1,1),매입장!$B$4:$B$1503,기본설정!$C$6))-IF(기본설정!$C$6="전체",SUMPRODUCT((재고실사!$W$4:$W$403="주류·음료")*재고실사!$E$4:$E$403*INDEX(재고실사!$F$4:$R$403,0,$A6+1)),SUMPRODUCT((재고실사!$W$4:$W$403="주류·음료")*(재고실사!$A$4:$A$403=기본설정!$C$6)*재고실사!$E$4:$E$403*INDEX(재고실사!$F$4:$R$403,0,$A6+1))) -> 0 | K6: =IFERROR(J6/D6,0) -> 0 | L6: =IF(기본설정!$C$6="전체",SUMPRODUCT((재고실사!$W$4:$W$403="소모품")*재고실사!$E$4:$E$403*INDEX(재고실사!$F$4:$R$403,0,$A6+0)),SUMPRODUCT((재고실사!$W$4:$W$403="소모품")*(재고실사!$A$4:$A$403=기본설정!$C$6)*재고실사!$E$4:$E$403*INDEX(재고실사!$F$4:$R$403,0,$A6+0)))+IF(기본설정!$C$6="전체",SUMIFS(매입장!$I$4:$I$1503,매입장!$P$4:$P$1503,"소모품",매입장!$A$4:$A$1503,">="&DATE(기본설정!$C$4,$A6,1),매입장!$A$4:$A$1503,"<"&DATE(기본설정!$C$4,$A6+1,1)),SUMIFS(매입장!$I$4:$I$1503,매입장!$P$4:$P$1503,"소모품",매입장!$A$4:$A$1503,">="&DATE(기본설정!$C$4,$A6,1),매입장!$A$4:$A$1503,"<"&DATE(기본설정!$C$4,$A6+1,1),매입장!$B$4:$B$1503,기본설정!$C$6))-IF(기본설정!$C$6="전체",SUMPRODUCT((재고실사!$W$4:$W$403="소모품")*재고실사!$E$4:$E$403*INDEX(재고실사!$F$4:$R$403,0,$A6+1)),SUMPRODUCT((재고실사!$W$4:$W$403="소모품")*(재고실사!$A$4:$A$403=기본설정!$C$6)*재고실사!$E$4:$E$403*INDEX(재고실사!$F$4:$R$403,0,$A6+1))) -> 0 | M6: =G6+J6+L6 -> 0 | N6: =IFERROR(M6/E6,0) -> 0 | O6: =E6-M6 -> 0 | P6: =IFERROR(O6/E6,0) -> 0 | Q6: =IF(기본설정!$C$6="전체",SUMIFS(매출일보!$J$4:$J$403,매출일보!$A$4:$A$403,">="&DATE(기본설정!$C$4,$A6,1),매출일보!$A$4:$A$403,"<"&DATE(기본설정!$C$4,$A6+1,1)),SUMIFS(매출일보!$J$4:$J$403,매출일보!$A$4:$A$403,">="&DATE(기본설정!$C$4,$A6,1),매출일보!$A$4:$A$403,"<"&DATE(기본설정!$C$4,$A6+1,1),매출일보!$B$4:$B$403,기본설정!$C$6)) -> 0 | R6: =IFERROR(B6/Q6,0) -> 0 | S6: =IF(SUMPRODUCT(--(INDEX(재고실사!$F$4:$R$403,0,$A6+1)<>""))>0,"입력","미입력") -> 미입력
A7: 3 | B7: =IF(기본설정!$C$6="전체",SUMIFS(매출일보!$G$4:$G$403,매출일보!$A$4:$A$403,">="&DATE(기본설정!$C$4,$A7,1),매출일보!$A$4:$A$403,"<"&DATE(기본설정!$C$4,$A7+1,1)),SUMIFS(매출일보!$G$4:$G$403,매출일보!$A$4:$A$403,">="&DATE(기본설정!$C$4,$A7,1),매출일보!$A$4:$A$403,"<"&DATE(기본설정!$C$4,$A7+1,1),매출일보!$B$4:$B$403,기본설정!$C$6)) -> 0 | C7: =IF(기본설정!$C$6="전체",SUMIFS(매출일보!$I$4:$I$403,매출일보!$A$4:$A$403,">="&DATE(기본설정!$C$4,$A7,1),매출일보!$A$4:$A$403,"<"&DATE(기본설정!$C$4,$A7+1,1)),SUMIFS(매출일보!$I$4:$I$403,매출일보!$A$4:$A$403,">="&DATE(기본설정!$C$4,$A7,1),매출일보!$A$4:$A$403,"<"&DATE(기본설정!$C$4,$A7+1,1),매출일보!$B$4:$B$403,기본설정!$C$6))/1.1 -> 0 | D7: =IF(기본설정!$C$6="전체",SUMIFS(매출일보!$H$4:$H$403,매출일보!$A$4:$A$403,">="&DATE(기본설정!$C$4,$A7,1),매출일보!$A$4:$A$403,"<"&DATE(기본설정!$C$4,$A7+1,1)),SUMIFS(매출일보!$H$4:$H$403,매출일보!$A$4:$A$403,">="&DATE(기본설정!$C$4,$A7,1),매출일보!$A$4:$A$403,"<"&DATE(기본설정!$C$4,$A7+1,1),매출일보!$B$4:$B$403,기본설정!$C$6))/1.1 -> 0 | E7: =C7+D7 -> 0 | F7: =IF(기본설정!$C$6="전체",SUMIFS(매입장!$I$4:$I$1503,매입장!$P$4:$P$1503,"식재료",매입장!$A$4:$A$1503,">="&DATE(기본설정!$C$4,$A7,1),매입장!$A$4:$A$1503,"<"&DATE(기본설정!$C$4,$A7+1,1)),SUMIFS(매입장!$I$4:$I$1503,매입장!$P$4:$P$1503,"식재료",매입장!$A$4:$A$1503,">="&DATE(기본설정!$C$4,$A7,1),매입장!$A$4:$A$1503,"<"&DATE(기본설정!$C$4,$A7+1,1),매입장!$B$4:$B$1503,기본설정!$C$6)) -> 0 | G7: =IF(기본설정!$C$6="전체",SUMPRODUCT((재고실사!$W$4:$W$403="식재료")*재고실사!$E$4:$E$403*INDEX(재고실사!$F$4:$R$403,0,$A7+0)),SUMPRODUCT((재고실사!$W$4:$W$403="식재료")*(재고실사!$A$4:$A$403=기본설정!$C$6)*재고실사!$E$4:$E$403*INDEX(재고실사!$F$4:$R$403,0,$A7+0)))+IF(기본설정!$C$6="전체",SUMIFS(매입장!$I$4:$I$1503,매입장!$P$4:$P$1503,"식재료",매입장!$A$4:$A$1503,">="&DATE(기본설정!$C$4,$A7,1),매입장!$A$4:$A$1503,"<"&DATE(기본설정!$C$4,$A7+1,1)),SUMIFS(매입장!$I$4:$I$1503,매입장!$P$4:$P$1503,"식재료",매입장!$A$4:$A$1503,">="&DATE(기본설정!$C$4,$A7,1),매입장!$A$4:$A$1503,"<"&DATE(기본설정!$C$4,$A7+1,1),매입장!$B$4:$B$1503,기본설정!$C$6))-IF(기본설정!$C$6="전체",SUMPRODUCT((재고실사!$W$4:$W$403="식재료")*재고실사!$E$4:$E$403*INDEX(재고실사!$F$4:$R$403,0,$A7+1)),SUMPRODUCT((재고실사!$W$4:$W$403="식재료")*(재고실사!$A$4:$A$403=기본설정!$C$6)*재고실사!$E$4:$E$403*INDEX(재고실사!$F$4:$R$403,0,$A7+1))) -> 0 | H7: =IFERROR(G7/C7,0) -> 0 | I7: =IF(기본설정!$C$6="전체",SUMIFS(매입장!$I$4:$I$1503,매입장!$P$4:$P$1503,"주류·음료",매입장!$A$4:$A$1503,">="&DATE(기본설정!$C$4,$A7,1),매입장!$A$4:$A$1503,"<"&DATE(기본설정!$C$4,$A7+1,1)),SUMIFS(매입장!$I$4:$I$1503,매입장!$P$4:$P$1503,"주류·음료",매입장!$A$4:$A$1503,">="&DATE(기본설정!$C$4,$A7,1),매입장!$A$4:$A$1503,"<"&DATE(기본설정!$C$4,$A7+1,1),매입장!$B$4:$B$1503,기본설정!$C$6)) -> 0 | J7: =IF(기본설정!$C$6="전체",SUMPRODUCT((재고실사!$W$4:$W$403="주류·음료")*재고실사!$E$4:$E$403*INDEX(재고실사!$F$4:$R$403,0,$A7+0)),SUMPRODUCT((재고실사!$W$4:$W$403="주류·음료")*(재고실사!$A$4:$A$403=기본설정!$C$6)*재고실사!$E$4:$E$403*INDEX(재고실사!$F$4:$R$403,0,$A7+0)))+IF(기본설정!$C$6="전체",SUMIFS(매입장!$I$4:$I$1503,매입장!$P$4:$P$1503,"주류·음료",매입장!$A$4:$A$1503,">="&DATE(기본설정!$C$4,$A7,1),매입장!$A$4:$A$1503,"<"&DATE(기본설정!$C$4,$A7+1,1)),SUMIFS(매입장!$I$4:$I$1503,매입장!$P$4:$P$1503,"주류·음료",매입장!$A$4:$A$1503,">="&DATE(기본설정!$C$4,$A7,1),매입장!$A$4:$A$1503,"<"&DATE(기본설정!$C$4,$A7+1,1),매입장!$B$4:$B$1503,기본설정!$C$6))-IF(기본설정!$C$6="전체",SUMPRODUCT((재고실사!$W$4:$W$403="주류·음료")*재고실사!$E$4:$E$403*INDEX(재고실사!$F$4:$R$403,0,$A7+1)),SUMPRODUCT((재고실사!$W$4:$W$403="주류·음료")*(재고실사!$A$4:$A$403=기본설정!$C$6)*재고실사!$E$4:$E$403*INDEX(재고실사!$F$4:$R$403,0,$A7+1))) -> 0 | K7: =IFERROR(J7/D7,0) -> 0 | L7: =IF(기본설정!$C$6="전체",SUMPRODUCT((재고실사!$W$4:$W$403="소모품")*재고실사!$E$4:$E$403*INDEX(재고실사!$F$4:$R$403,0,$A7+0)),SUMPRODUCT((재고실사!$W$4:$W$403="소모품")*(재고실사!$A$4:$A$403=기본설정!$C$6)*재고실사!$E$4:$E$403*INDEX(재고실사!$F$4:$R$403,0,$A7+0)))+IF(기본설정!$C$6="전체",SUMIFS(매입장!$I$4:$I$1503,매입장!$P$4:$P$1503,"소모품",매입장!$A$4:$A$1503,">="&DATE(기본설정!$C$4,$A7,1),매입장!$A$4:$A$1503,"<"&DATE(기본설정!$C$4,$A7+1,1)),SUMIFS(매입장!$I$4:$I$1503,매입장!$P$4:$P$1503,"소모품",매입장!$A$4:$A$1503,">="&DATE(기본설정!$C$4,$A7,1),매입장!$A$4:$A$1503,"<"&DATE(기본설정!$C$4,$A7+1,1),매입장!$B$4:$B$1503,기본설정!$C$6))-IF(기본설정!$C$6="전체",SUMPRODUCT((재고실사!$W$4:$W$403="소모품")*재고실사!$E$4:$E$403*INDEX(재고실사!$F$4:$R$403,0,$A7+1)),SUMPRODUCT((재고실사!$W$4:$W$403="소모품")*(재고실사!$A$4:$A$403=기본설정!$C$6)*재고실사!$E$4:$E$403*INDEX(재고실사!$F$4:$R$403,0,$A7+1))) -> 0 | M7: =G7+J7+L7 -> 0 | N7: =IFERROR(M7/E7,0) -> 0 | O7: =E7-M7 -> 0 | P7: =IFERROR(O7/E7,0) -> 0 | Q7: =IF(기본설정!$C$6="전체",SUMIFS(매출일보!$J$4:$J$403,매출일보!$A$4:$A$403,">="&DATE(기본설정!$C$4,$A7,1),매출일보!$A$4:$A$403,"<"&DATE(기본설정!$C$4,$A7+1,1)),SUMIFS(매출일보!$J$4:$J$403,매출일보!$A$4:$A$403,">="&DATE(기본설정!$C$4,$A7,1),매출일보!$A$4:$A$403,"<"&DATE(기본설정!$C$4,$A7+1,1),매출일보!$B$4:$B$403,기본설정!$C$6)) -> 0 | R7: =IFERROR(B7/Q7,0) -> 0 | S7: =IF(SUMPRODUCT(--(INDEX(재고실사!$F$4:$R$403,0,$A7+1)<>""))>0,"입력","미입력") -> 미입력
A8: 4 | B8: =IF(기본설정!$C$6="전체",SUMIFS(매출일보!$G$4:$G$403,매출일보!$A$4:$A$403,">="&DATE(기본설정!$C$4,$A8,1),매출일보!$A$4:$A$403,"<"&DATE(기본설정!$C$4,$A8+1,1)),SUMIFS(매출일보!$G$4:$G$403,매출일보!$A$4:$A$403,">="&DATE(기본설정!$C$4,$A8,1),매출일보!$A$4:$A$403,"<"&DATE(기본설정!$C$4,$A8+1,1),매출일보!$B$4:$B$403,기본설정!$C$6)) -> 0 | C8: =IF(기본설정!$C$6="전체",SUMIFS(매출일보!$I$4:$I$403,매출일보!$A$4:$A$403,">="&DATE(기본설정!$C$4,$A8,1),매출일보!$A$4:$A$403,"<"&DATE(기본설정!$C$4,$A8+1,1)),SUMIFS(매출일보!$I$4:$I$403,매출일보!$A$4:$A$403,">="&DATE(기본설정!$C$4,$A8,1),매출일보!$A$4:$A$403,"<"&DATE(기본설정!$C$4,$A8+1,1),매출일보!$B$4:$B$403,기본설정!$C$6))/1.1 -> 0 | D8: =IF(기본설정!$C$6="전체",SUMIFS(매출일보!$H$4:$H$403,매출일보!$A$4:$A$403,">="&DATE(기본설정!$C$4,$A8,1),매출일보!$A$4:$A$403,"<"&DATE(기본설정!$C$4,$A8+1,1)),SUMIFS(매출일보!$H$4:$H$403,매출일보!$A$4:$A$403,">="&DATE(기본설정!$C$4,$A8,1),매출일보!$A$4:$A$403,"<"&DATE(기본설정!$C$4,$A8+1,1),매출일보!$B$4:$B$403,기본설정!$C$6))/1.1 -> 0 | E8: =C8+D8 -> 0 | F8: =IF(기본설정!$C$6="전체",SUMIFS(매입장!$I$4:$I$1503,매입장!$P$4:$P$1503,"식재료",매입장!$A$4:$A$1503,">="&DATE(기본설정!$C$4,$A8,1),매입장!$A$4:$A$1503,"<"&DATE(기본설정!$C$4,$A8+1,1)),SUMIFS(매입장!$I$4:$I$1503,매입장!$P$4:$P$1503,"식재료",매입장!$A$4:$A$1503,">="&DATE(기본설정!$C$4,$A8,1),매입장!$A$4:$A$1503,"<"&DATE(기본설정!$C$4,$A8+1,1),매입장!$B$4:$B$1503,기본설정!$C$6)) -> 0 | G8: =IF(기본설정!$C$6="전체",SUMPRODUCT((재고실사!$W$4:$W$403="식재료")*재고실사!$E$4:$E$403*INDEX(재고실사!$F$4:$R$403,0,$A8+0)),SUMPRODUCT((재고실사!$W$4:$W$403="식재료")*(재고실사!$A$4:$A$403=기본설정!$C$6)*재고실사!$E$4:$E$403*INDEX(재고실사!$F$4:$R$403,0,$A8+0)))+IF(기본설정!$C$6="전체",SUMIFS(매입장!$I$4:$I$1503,매입장!$P$4:$P$1503,"식재료",매입장!$A$4:$A$1503,">="&DATE(기본설정!$C$4,$A8,1),매입장!$A$4:$A$1503,"<"&DATE(기본설정!$C$4,$A8+1,1)),SUMIFS(매입장!$I$4:$I$1503,매입장!$P$4:$P$1503,"식재료",매입장!$A$4:$A$1503,">="&DATE(기본설정!$C$4,$A8,1),매입장!$A$4:$A$1503,"<"&DATE(기본설정!$C$4,$A8+1,1),매입장!$B$4:$B$1503,기본설정!$C$6))-IF(기본설정!$C$6="전체",SUMPRODUCT((재고실사!$W$4:$W$403="식재료")*재고실사!$E$4:$E$403*INDEX(재고실사!$F$4:$R$403,0,$A8+1)),SUMPRODUCT((재고실사!$W$4:$W$403="식재료")*(재고실사!$A$4:$A$403=기본설정!$C$6)*재고실사!$E$4:$E$403*INDEX(재고실사!$F$4:$R$403,0,$A8+1))) -> 0 | H8: =IFERROR(G8/C8,0) -> 0 | I8: =IF(기본설정!$C$6="전체",SUMIFS(매입장!$I$4:$I$1503,매입장!$P$4:$P$1503,"주류·음료",매입장!$A$4:$A$1503,">="&DATE(기본설정!$C$4,$A8,1),매입장!$A$4:$A$1503,"<"&DATE(기본설정!$C$4,$A8+1,1)),SUMIFS(매입장!$I$4:$I$1503,매입장!$P$4:$P$1503,"주류·음료",매입장!$A$4:$A$1503,">="&DATE(기본설정!$C$4,$A8,1),매입장!$A$4:$A$1503,"<"&DATE(기본설정!$C$4,$A8+1,1),매입장!$B$4:$B$1503,기본설정!$C$6)) -> 0 | J8: =IF(기본설정!$C$6="전체",SUMPRODUCT((재고실사!$W$4:$W$403="주류·음료")*재고실사!$E$4:$E$403*INDEX(재고실사!$F$4:$R$403,0,$A8+0)),SUMPRODUCT((재고실사!$W$4:$W$403="주류·음료")*(재고실사!$A$4:$A$403=기본설정!$C$6)*재고실사!$E$4:$E$403*INDEX(재고실사!$F$4:$R$403,0,$A8+0)))+IF(기본설정!$C$6="전체",SUMIFS(매입장!$I$4:$I$1503,매입장!$P$4:$P$1503,"주류·음료",매입장!$A$4:$A$1503,">="&DATE(기본설정!$C$4,$A8,1),매입장!$A$4:$A$1503,"<"&DATE(기본설정!$C$4,$A8+1,1)),SUMIFS(매입장!$I$4:$I$1503,매입장!$P$4:$P$1503,"주류·음료",매입장!$A$4:$A$1503,">="&DATE(기본설정!$C$4,$A8,1),매입장!$A$4:$A$1503,"<"&DATE(기본설정!$C$4,$A8+1,1),매입장!$B$4:$B$1503,기본설정!$C$6))-IF(기본설정!$C$6="전체",SUMPRODUCT((재고실사!$W$4:$W$403="주류·음료")*재고실사!$E$4:$E$403*INDEX(재고실사!$F$4:$R$403,0,$A8+1)),SUMPRODUCT((재고실사!$W$4:$W$403="주류·음료")*(재고실사!$A$4:$A$403=기본설정!$C$6)*재고실사!$E$4:$E$403*INDEX(재고실사!$F$4:$R$403,0,$A8+1))) -> 0 | K8: =IFERROR(J8/D8,0) -> 0 | L8: =IF(기본설정!$C$6="전체",SUMPRODUCT((재고실사!$W$4:$W$403="소모품")*재고실사!$E$4:$E$403*INDEX(재고실사!$F$4:$R$403,0,$A8+0)),SUMPRODUCT((재고실사!$W$4:$W$403="소모품")*(재고실사!$A$4:$A$403=기본설정!$C$6)*재고실사!$E$4:$E$403*INDEX(재고실사!$F$4:$R$403,0,$A8+0)))+IF(기본설정!$C$6="전체",SUMIFS(매입장!$I$4:$I$1503,매입장!$P$4:$P$1503,"소모품",매입장!$A$4:$A$1503,">="&DATE(기본설정!$C$4,$A8,1),매입장!$A$4:$A$1503,"<"&DATE(기본설정!$C$4,$A8+1,1)),SUMIFS(매입장!$I$4:$I$1503,매입장!$P$4:$P$1503,"소모품",매입장!$A$4:$A$1503,">="&DATE(기본설정!$C$4,$A8,1),매입장!$A$4:$A$1503,"<"&DATE(기본설정!$C$4,$A8+1,1),매입장!$B$4:$B$1503,기본설정!$C$6))-IF(기본설정!$C$6="전체",SUMPRODUCT((재고실사!$W$4:$W$403="소모품")*재고실사!$E$4:$E$403*INDEX(재고실사!$F$4:$R$403,0,$A8+1)),SUMPRODUCT((재고실사!$W$4:$W$403="소모품")*(재고실사!$A$4:$A$403=기본설정!$C$6)*재고실사!$E$4:$E$403*INDEX(재고실사!$F$4:$R$403,0,$A8+1))) -> 0 | M8: =G8+J8+L8 -> 0 | N8: =IFERROR(M8/E8,0) -> 0 | O8: =E8-M8 -> 0 | P8: =IFERROR(O8/E8,0) -> 0 | Q8: =IF(기본설정!$C$6="전체",SUMIFS(매출일보!$J$4:$J$403,매출일보!$A$4:$A$403,">="&DATE(기본설정!$C$4,$A8,1),매출일보!$A$4:$A$403,"<"&DATE(기본설정!$C$4,$A8+1,1)),SUMIFS(매출일보!$J$4:$J$403,매출일보!$A$4:$A$403,">="&DATE(기본설정!$C$4,$A8,1),매출일보!$A$4:$A$403,"<"&DATE(기본설정!$C$4,$A8+1,1),매출일보!$B$4:$B$403,기본설정!$C$6)) -> 0 | R8: =IFERROR(B8/Q8,0) -> 0 | S8: =IF(SUMPRODUCT(--(INDEX(재고실사!$F$4:$R$403,0,$A8+1)<>""))>0,"입력","미입력") -> 미입력
A9: 5 | B9: =IF(기본설정!$C$6="전체",SUMIFS(매출일보!$G$4:$G$403,매출일보!$A$4:$A$403,">="&DATE(기본설정!$C$4,$A9,1),매출일보!$A$4:$A$403,"<"&DATE(기본설정!$C$4,$A9+1,1)),SUMIFS(매출일보!$G$4:$G$403,매출일보!$A$4:$A$403,">="&DATE(기본설정!$C$4,$A9,1),매출일보!$A$4:$A$403,"<"&DATE(기본설정!$C$4,$A9+1,1),매출일보!$B$4:$B$403,기본설정!$C$6)) -> 0 | C9: =IF(기본설정!$C$6="전체",SUMIFS(매출일보!$I$4:$I$403,매출일보!$A$4:$A$403,">="&DATE(기본설정!$C$4,$A9,1),매출일보!$A$4:$A$403,"<"&DATE(기본설정!$C$4,$A9+1,1)),SUMIFS(매출일보!$I$4:$I$403,매출일보!$A$4:$A$403,">="&DATE(기본설정!$C$4,$A9,1),매출일보!$A$4:$A$403,"<"&DATE(기본설정!$C$4,$A9+1,1),매출일보!$B$4:$B$403,기본설정!$C$6))/1.1 -> 0 | D9: =IF(기본설정!$C$6="전체",SUMIFS(매출일보!$H$4:$H$403,매출일보!$A$4:$A$403,">="&DATE(기본설정!$C$4,$A9,1),매출일보!$A$4:$A$403,"<"&DATE(기본설정!$C$4,$A9+1,1)),SUMIFS(매출일보!$H$4:$H$403,매출일보!$A$4:$A$403,">="&DATE(기본설정!$C$4,$A9,1),매출일보!$A$4:$A$403,"<"&DATE(기본설정!$C$4,$A9+1,1),매출일보!$B$4:$B$403,기본설정!$C$6))/1.1 -> 0 | E9: =C9+D9 -> 0 | F9: =IF(기본설정!$C$6="전체",SUMIFS(매입장!$I$4:$I$1503,매입장!$P$4:$P$1503,"식재료",매입장!$A$4:$A$1503,">="&DATE(기본설정!$C$4,$A9,1),매입장!$A$4:$A$1503,"<"&DATE(기본설정!$C$4,$A9+1,1)),SUMIFS(매입장!$I$4:$I$1503,매입장!$P$4:$P$1503,"식재료",매입장!$A$4:$A$1503,">="&DATE(기본설정!$C$4,$A9,1),매입장!$A$4:$A$1503,"<"&DATE(기본설정!$C$4,$A9+1,1),매입장!$B$4:$B$1503,기본설정!$C$6)) -> 0 | G9: =IF(기본설정!$C$6="전체",SUMPRODUCT((재고실사!$W$4:$W$403="식재료")*재고실사!$E$4:$E$403*INDEX(재고실사!$F$4:$R$403,0,$A9+0)),SUMPRODUCT((재고실사!$W$4:$W$403="식재료")*(재고실사!$A$4:$A$403=기본설정!$C$6)*재고실사!$E$4:$E$403*INDEX(재고실사!$F$4:$R$403,0,$A9+0)))+IF(기본설정!$C$6="전체",SUMIFS(매입장!$I$4:$I$1503,매입장!$P$4:$P$1503,"식재료",매입장!$A$4:$A$1503,">="&DATE(기본설정!$C$4,$A9,1),매입장!$A$4:$A$1503,"<"&DATE(기본설정!$C$4,$A9+1,1)),SUMIFS(매입장!$I$4:$I$1503,매입장!$P$4:$P$1503,"식재료",매입장!$A$4:$A$1503,">="&DATE(기본설정!$C$4,$A9,1),매입장!$A$4:$A$1503,"<"&DATE(기본설정!$C$4,$A9+1,1),매입장!$B$4:$B$1503,기본설정!$C$6))-IF(기본설정!$C$6="전체",SUMPRODUCT((재고실사!$W$4:$W$403="식재료")*재고실사!$E$4:$E$403*INDEX(재고실사!$F$4:$R$403,0,$A9+1)),SUMPRODUCT((재고실사!$W$4:$W$403="식재료")*(재고실사!$A$4:$A$403=기본설정!$C$6)*재고실사!$E$4:$E$403*INDEX(재고실사!$F$4:$R$403,0,$A9+1))) -> 0 | H9: =IFERROR(G9/C9,0) -> 0 | I9: =IF(기본설정!$C$6="전체",SUMIFS(매입장!$I$4:$I$1503,매입장!$P$4:$P$1503,"주류·음료",매입장!$A$4:$A$1503,">="&DATE(기본설정!$C$4,$A9,1),매입장!$A$4:$A$1503,"<"&DATE(기본설정!$C$4,$A9+1,1)),SUMIFS(매입장!$I$4:$I$1503,매입장!$P$4:$P$1503,"주류·음료",매입장!$A$4:$A$1503,">="&DATE(기본설정!$C$4,$A9,1),매입장!$A$4:$A$1503,"<"&DATE(기본설정!$C$4,$A9+1,1),매입장!$B$4:$B$1503,기본설정!$C$6)) -> 0 | J9: =IF(기본설정!$C$6="전체",SUMPRODUCT((재고실사!$W$4:$W$403="주류·음료")*재고실사!$E$4:$E$403*INDEX(재고실사!$F$4:$R$403,0,$A9+0)),SUMPRODUCT((재고실사!$W$4:$W$403="주류·음료")*(재고실사!$A$4:$A$403=기본설정!$C$6)*재고실사!$E$4:$E$403*INDEX(재고실사!$F$4:$R$403,0,$A9+0)))+IF(기본설정!$C$6="전체",SUMIFS(매입장!$I$4:$I$1503,매입장!$P$4:$P$1503,"주류·음료",매입장!$A$4:$A$1503,">="&DATE(기본설정!$C$4,$A9,1),매입장!$A$4:$A$1503,"<"&DATE(기본설정!$C$4,$A9+1,1)),SUMIFS(매입장!$I$4:$I$1503,매입장!$P$4:$P$1503,"주류·음료",매입장!$A$4:$A$1503,">="&DATE(기본설정!$C$4,$A9,1),매입장!$A$4:$A$1503,"<"&DATE(기본설정!$C$4,$A9+1,1),매입장!$B$4:$B$1503,기본설정!$C$6))-IF(기본설정!$C$6="전체",SUMPRODUCT((재고실사!$W$4:$W$403="주류·음료")*재고실사!$E$4:$E$403*INDEX(재고실사!$F$4:$R$403,0,$A9+1)),SUMPRODUCT((재고실사!$W$4:$W$403="주류·음료")*(재고실사!$A$4:$A$403=기본설정!$C$6)*재고실사!$E$4:$E$403*INDEX(재고실사!$F$4:$R$403,0,$A9+1))) -> 0 | K9: =IFERROR(J9/D9,0) -> 0 | L9: =IF(기본설정!$C$6="전체",SUMPRODUCT((재고실사!$W$4:$W$403="소모품")*재고실사!$E$4:$E$403*INDEX(재고실사!$F$4:$R$403,0,$A9+0)),SUMPRODUCT((재고실사!$W$4:$W$403="소모품")*(재고실사!$A$4:$A$403=기본설정!$C$6)*재고실사!$E$4:$E$403*INDEX(재고실사!$F$4:$R$403,0,$A9+0)))+IF(기본설정!$C$6="전체",SUMIFS(매입장!$I$4:$I$1503,매입장!$P$4:$P$1503,"소모품",매입장!$A$4:$A$1503,">="&DATE(기본설정!$C$4,$A9,1),매입장!$A$4:$A$1503,"<"&DATE(기본설정!$C$4,$A9+1,1)),SUMIFS(매입장!$I$4:$I$1503,매입장!$P$4:$P$1503,"소모품",매입장!$A$4:$A$1503,">="&DATE(기본설정!$C$4,$A9,1),매입장!$A$4:$A$1503,"<"&DATE(기본설정!$C$4,$A9+1,1),매입장!$B$4:$B$1503,기본설정!$C$6))-IF(기본설정!$C$6="전체",SUMPRODUCT((재고실사!$W$4:$W$403="소모품")*재고실사!$E$4:$E$403*INDEX(재고실사!$F$4:$R$403,0,$A9+1)),SUMPRODUCT((재고실사!$W$4:$W$403="소모품")*(재고실사!$A$4:$A$403=기본설정!$C$6)*재고실사!$E$4:$E$403*INDEX(재고실사!$F$4:$R$403,0,$A9+1))) -> 0 | M9: =G9+J9+L9 -> 0 | N9: =IFERROR(M9/E9,0) -> 0 | O9: =E9-M9 -> 0 | P9: =IFERROR(O9/E9,0) -> 0 | Q9: =IF(기본설정!$C$6="전체",SUMIFS(매출일보!$J$4:$J$403,매출일보!$A$4:$A$403,">="&DATE(기본설정!$C$4,$A9,1),매출일보!$A$4:$A$403,"<"&DATE(기본설정!$C$4,$A9+1,1)),SUMIFS(매출일보!$J$4:$J$403,매출일보!$A$4:$A$403,">="&DATE(기본설정!$C$4,$A9,1),매출일보!$A$4:$A$403,"<"&DATE(기본설정!$C$4,$A9+1,1),매출일보!$B$4:$B$403,기본설정!$C$6)) -> 0 | R9: =IFERROR(B9/Q9,0) -> 0 | S9: =IF(SUMPRODUCT(--(INDEX(재고실사!$F$4:$R$403,0,$A9+1)<>""))>0,"입력","미입력") -> 미입력
A10: 6 | B10: =IF(기본설정!$C$6="전체",SUMIFS(매출일보!$G$4:$G$403,매출일보!$A$4:$A$403,">="&DATE(기본설정!$C$4,$A10,1),매출일보!$A$4:$A$403,"<"&DATE(기본설정!$C$4,$A10+1,1)),SUMIFS(매출일보!$G$4:$G$403,매출일보!$A$4:$A$403,">="&DATE(기본설정!$C$4,$A10,1),매출일보!$A$4:$A$403,"<"&DATE(기본설정!$C$4,$A10+1,1),매출일보!$B$4:$B$403,기본설정!$C$6)) -> 0 | C10: =IF(기본설정!$C$6="전체",SUMIFS(매출일보!$I$4:$I$403,매출일보!$A$4:$A$403,">="&DATE(기본설정!$C$4,$A10,1),매출일보!$A$4:$A$403,"<"&DATE(기본설정!$C$4,$A10+1,1)),SUMIFS(매출일보!$I$4:$I$403,매출일보!$A$4:$A$403,">="&DATE(기본설정!$C$4,$A10,1),매출일보!$A$4:$A$403,"<"&DATE(기본설정!$C$4,$A10+1,1),매출일보!$B$4:$B$403,기본설정!$C$6))/1.1 -> 0 | D10: =IF(기본설정!$C$6="전체",SUMIFS(매출일보!$H$4:$H$403,매출일보!$A$4:$A$403,">="&DATE(기본설정!$C$4,$A10,1),매출일보!$A$4:$A$403,"<"&DATE(기본설정!$C$4,$A10+1,1)),SUMIFS(매출일보!$H$4:$H$403,매출일보!$A$4:$A$403,">="&DATE(기본설정!$C$4,$A10,1),매출일보!$A$4:$A$403,"<"&DATE(기본설정!$C$4,$A10+1,1),매출일보!$B$4:$B$403,기본설정!$C$6))/1.1 -> 0 | E10: =C10+D10 -> 0 | F10: =IF(기본설정!$C$6="전체",SUMIFS(매입장!$I$4:$I$1503,매입장!$P$4:$P$1503,"식재료",매입장!$A$4:$A$1503,">="&DATE(기본설정!$C$4,$A10,1),매입장!$A$4:$A$1503,"<"&DATE(기본설정!$C$4,$A10+1,1)),SUMIFS(매입장!$I$4:$I$1503,매입장!$P$4:$P$1503,"식재료",매입장!$A$4:$A$1503,">="&DATE(기본설정!$C$4,$A10,1),매입장!$A$4:$A$1503,"<"&DATE(기본설정!$C$4,$A10+1,1),매입장!$B$4:$B$1503,기본설정!$C$6)) -> 0 | G10: =IF(기본설정!$C$6="전체",SUMPRODUCT((재고실사!$W$4:$W$403="식재료")*재고실사!$E$4:$E$403*INDEX(재고실사!$F$4:$R$403,0,$A10+0)),SUMPRODUCT((재고실사!$W$4:$W$403="식재료")*(재고실사!$A$4:$A$403=기본설정!$C$6)*재고실사!$E$4:$E$403*INDEX(재고실사!$F$4:$R$403,0,$A10+0)))+IF(기본설정!$C$6="전체",SUMIFS(매입장!$I$4:$I$1503,매입장!$P$4:$P$1503,"식재료",매입장!$A$4:$A$1503,">="&DATE(기본설정!$C$4,$A10,1),매입장!$A$4:$A$1503,"<"&DATE(기본설정!$C$4,$A10+1,1)),SUMIFS(매입장!$I$4:$I$1503,매입장!$P$4:$P$1503,"식재료",매입장!$A$4:$A$1503,">="&DATE(기본설정!$C$4,$A10,1),매입장!$A$4:$A$1503,"<"&DATE(기본설정!$C$4,$A10+1,1),매입장!$B$4:$B$1503,기본설정!$C$6))-IF(기본설정!$C$6="전체",SUMPRODUCT((재고실사!$W$4:$W$403="식재료")*재고실사!$E$4:$E$403*INDEX(재고실사!$F$4:$R$403,0,$A10+1)),SUMPRODUCT((재고실사!$W$4:$W$403="식재료")*(재고실사!$A$4:$A$403=기본설정!$C$6)*재고실사!$E$4:$E$403*INDEX(재고실사!$F$4:$R$403,0,$A10+1))) -> 0 | H10: =IFERROR(G10/C10,0) -> 0 | I10: =IF(기본설정!$C$6="전체",SUMIFS(매입장!$I$4:$I$1503,매입장!$P$4:$P$1503,"주류·음료",매입장!$A$4:$A$1503,">="&DATE(기본설정!$C$4,$A10,1),매입장!$A$4:$A$1503,"<"&DATE(기본설정!$C$4,$A10+1,1)),SUMIFS(매입장!$I$4:$I$1503,매입장!$P$4:$P$1503,"주류·음료",매입장!$A$4:$A$1503,">="&DATE(기본설정!$C$4,$A10,1),매입장!$A$4:$A$1503,"<"&DATE(기본설정!$C$4,$A10+1,1),매입장!$B$4:$B$1503,기본설정!$C$6)) -> 0 | J10: =IF(기본설정!$C$6="전체",SUMPRODUCT((재고실사!$W$4:$W$403="주류·음료")*재고실사!$E$4:$E$403*INDEX(재고실사!$F$4:$R$403,0,$A10+0)),SUMPRODUCT((재고실사!$W$4:$W$403="주류·음료")*(재고실사!$A$4:$A$403=기본설정!$C$6)*재고실사!$E$4:$E$403*INDEX(재고실사!$F$4:$R$403,0,$A10+0)))+IF(기본설정!$C$6="전체",SUMIFS(매입장!$I$4:$I$1503,매입장!$P$4:$P$1503,"주류·음료",매입장!$A$4:$A$1503,">="&DATE(기본설정!$C$4,$A10,1),매입장!$A$4:$A$1503,"<"&DATE(기본설정!$C$4,$A10+1,1)),SUMIFS(매입장!$I$4:$I$1503,매입장!$P$4:$P$1503,"주류·음료",매입장!$A$4:$A$1503,">="&DATE(기본설정!$C$4,$A10,1),매입장!$A$4:$A$1503,"<"&DATE(기본설정!$C$4,$A10+1,1),매입장!$B$4:$B$1503,기본설정!$C$6))-IF(기본설정!$C$6="전체",SUMPRODUCT((재고실사!$W$4:$W$403="주류·음료")*재고실사!$E$4:$E$403*INDEX(재고실사!$F$4:$R$403,0,$A10+1)),SUMPRODUCT((재고실사!$W$4:$W$403="주류·음료")*(재고실사!$A$4:$A$403=기본설정!$C$6)*재고실사!$E$4:$E$403*INDEX(재고실사!$F$4:$R$403,0,$A10+1))) -> 0 | K10: =IFERROR(J10/D10,0) -> 0 | L10: =IF(기본설정!$C$6="전체",SUMPRODUCT((재고실사!$W$4:$W$403="소모품")*재고실사!$E$4:$E$403*INDEX(재고실사!$F$4:$R$403,0,$A10+0)),SUMPRODUCT((재고실사!$W$4:$W$403="소모품")*(재고실사!$A$4:$A$403=기본설정!$C$6)*재고실사!$E$4:$E$403*INDEX(재고실사!$F$4:$R$403,0,$A10+0)))+IF(기본설정!$C$6="전체",SUMIFS(매입장!$I$4:$I$1503,매입장!$P$4:$P$1503,"소모품",매입장!$A$4:$A$1503,">="&DATE(기본설정!$C$4,$A10,1),매입장!$A$4:$A$1503,"<"&DATE(기본설정!$C$4,$A10+1,1)),SUMIFS(매입장!$I$4:$I$1503,매입장!$P$4:$P$1503,"소모품",매입장!$A$4:$A$1503,">="&DATE(기본설정!$C$4,$A10,1),매입장!$A$4:$A$1503,"<"&DATE(기본설정!$C$4,$A10+1,1),매입장!$B$4:$B$1503,기본설정!$C$6))-IF(기본설정!$C$6="전체",SUMPRODUCT((재고실사!$W$4:$W$403="소모품")*재고실사!$E$4:$E$403*INDEX(재고실사!$F$4:$R$403,0,$A10+1)),SUMPRODUCT((재고실사!$W$4:$W$403="소모품")*(재고실사!$A$4:$A$403=기본설정!$C$6)*재고실사!$E$4:$E$403*INDEX(재고실사!$F$4:$R$403,0,$A10+1))) -> 0 | M10: =G10+J10+L10 -> 0 | N10: =IFERROR(M10/E10,0) -> 0 | O10: =E10-M10 -> 0 | P10: =IFERROR(O10/E10,0) -> 0 | Q10: =IF(기본설정!$C$6="전체",SUMIFS(매출일보!$J$4:$J$403,매출일보!$A$4:$A$403,">="&DATE(기본설정!$C$4,$A10,1),매출일보!$A$4:$A$403,"<"&DATE(기본설정!$C$4,$A10+1,1)),SUMIFS(매출일보!$J$4:$J$403,매출일보!$A$4:$A$403,">="&DATE(기본설정!$C$4,$A10,1),매출일보!$A$4:$A$403,"<"&DATE(기본설정!$C$4,$A10+1,1),매출일보!$B$4:$B$403,기본설정!$C$6)) -> 0 | R10: =IFERROR(B10/Q10,0) -> 0 | S10: =IF(SUMPRODUCT(--(INDEX(재고실사!$F$4:$R$403,0,$A10+1)<>""))>0,"입력","미입력") -> 미입력
A11: 7 | B11: =IF(기본설정!$C$6="전체",SUMIFS(매출일보!$G$4:$G$403,매출일보!$A$4:$A$403,">="&DATE(기본설정!$C$4,$A11,1),매출일보!$A$4:$A$403,"<"&DATE(기본설정!$C$4,$A11+1,1)),SUMIFS(매출일보!$G$4:$G$403,매출일보!$A$4:$A$403,">="&DATE(기본설정!$C$4,$A11,1),매출일보!$A$4:$A$403,"<"&DATE(기본설정!$C$4,$A11+1,1),매출일보!$B$4:$B$403,기본설정!$C$6)) -> 0 | C11: =IF(기본설정!$C$6="전체",SUMIFS(매출일보!$I$4:$I$403,매출일보!$A$4:$A$403,">="&DATE(기본설정!$C$4,$A11,1),매출일보!$A$4:$A$403,"<"&DATE(기본설정!$C$4,$A11+1,1)),SUMIFS(매출일보!$I$4:$I$403,매출일보!$A$4:$A$403,">="&DATE(기본설정!$C$4,$A11,1),매출일보!$A$4:$A$403,"<"&DATE(기본설정!$C$4,$A11+1,1),매출일보!$B$4:$B$403,기본설정!$C$6))/1.1 -> 0 | D11: =IF(기본설정!$C$6="전체",SUMIFS(매출일보!$H$4:$H$403,매출일보!$A$4:$A$403,">="&DATE(기본설정!$C$4,$A11,1),매출일보!$A$4:$A$403,"<"&DATE(기본설정!$C$4,$A11+1,1)),SUMIFS(매출일보!$H$4:$H$403,매출일보!$A$4:$A$403,">="&DATE(기본설정!$C$4,$A11,1),매출일보!$A$4:$A$403,"<"&DATE(기본설정!$C$4,$A11+1,1),매출일보!$B$4:$B$403,기본설정!$C$6))/1.1 -> 0 | E11: =C11+D11 -> 0 | F11: =IF(기본설정!$C$6="전체",SUMIFS(매입장!$I$4:$I$1503,매입장!$P$4:$P$1503,"식재료",매입장!$A$4:$A$1503,">="&DATE(기본설정!$C$4,$A11,1),매입장!$A$4:$A$1503,"<"&DATE(기본설정!$C$4,$A11+1,1)),SUMIFS(매입장!$I$4:$I$1503,매입장!$P$4:$P$1503,"식재료",매입장!$A$4:$A$1503,">="&DATE(기본설정!$C$4,$A11,1),매입장!$A$4:$A$1503,"<"&DATE(기본설정!$C$4,$A11+1,1),매입장!$B$4:$B$1503,기본설정!$C$6)) -> 0 | G11: =IF(기본설정!$C$6="전체",SUMPRODUCT((재고실사!$W$4:$W$403="식재료")*재고실사!$E$4:$E$403*INDEX(재고실사!$F$4:$R$403,0,$A11+0)),SUMPRODUCT((재고실사!$W$4:$W$403="식재료")*(재고실사!$A$4:$A$403=기본설정!$C$6)*재고실사!$E$4:$E$403*INDEX(재고실사!$F$4:$R$403,0,$A11+0)))+IF(기본설정!$C$6="전체",SUMIFS(매입장!$I$4:$I$1503,매입장!$P$4:$P$1503,"식재료",매입장!$A$4:$A$1503,">="&DATE(기본설정!$C$4,$A11,1),매입장!$A$4:$A$1503,"<"&DATE(기본설정!$C$4,$A11+1,1)),SUMIFS(매입장!$I$4:$I$1503,매입장!$P$4:$P$1503,"식재료",매입장!$A$4:$A$1503,">="&DATE(기본설정!$C$4,$A11,1),매입장!$A$4:$A$1503,"<"&DATE(기본설정!$C$4,$A11+1,1),매입장!$B$4:$B$1503,기본설정!$C$6))-IF(기본설정!$C$6="전체",SUMPRODUCT((재고실사!$W$4:$W$403="식재료")*재고실사!$E$4:$E$403*INDEX(재고실사!$F$4:$R$403,0,$A11+1)),SUMPRODUCT((재고실사!$W$4:$W$403="식재료")*(재고실사!$A$4:$A$403=기본설정!$C$6)*재고실사!$E$4:$E$403*INDEX(재고실사!$F$4:$R$403,0,$A11+1))) -> 0 | H11: =IFERROR(G11/C11,0) -> 0 | I11: =IF(기본설정!$C$6="전체",SUMIFS(매입장!$I$4:$I$1503,매입장!$P$4:$P$1503,"주류·음료",매입장!$A$4:$A$1503,">="&DATE(기본설정!$C$4,$A11,1),매입장!$A$4:$A$1503,"<"&DATE(기본설정!$C$4,$A11+1,1)),SUMIFS(매입장!$I$4:$I$1503,매입장!$P$4:$P$1503,"주류·음료",매입장!$A$4:$A$1503,">="&DATE(기본설정!$C$4,$A11,1),매입장!$A$4:$A$1503,"<"&DATE(기본설정!$C$4,$A11+1,1),매입장!$B$4:$B$1503,기본설정!$C$6)) -> 0 | J11: =IF(기본설정!$C$6="전체",SUMPRODUCT((재고실사!$W$4:$W$403="주류·음료")*재고실사!$E$4:$E$403*INDEX(재고실사!$F$4:$R$403,0,$A11+0)),SUMPRODUCT((재고실사!$W$4:$W$403="주류·음료")*(재고실사!$A$4:$A$403=기본설정!$C$6)*재고실사!$E$4:$E$403*INDEX(재고실사!$F$4:$R$403,0,$A11+0)))+IF(기본설정!$C$6="전체",SUMIFS(매입장!$I$4:$I$1503,매입장!$P$4:$P$1503,"주류·음료",매입장!$A$4:$A$1503,">="&DATE(기본설정!$C$4,$A11,1),매입장!$A$4:$A$1503,"<"&DATE(기본설정!$C$4,$A11+1,1)),SUMIFS(매입장!$I$4:$I$1503,매입장!$P$4:$P$1503,"주류·음료",매입장!$A$4:$A$1503,">="&DATE(기본설정!$C$4,$A11,1),매입장!$A$4:$A$1503,"<"&DATE(기본설정!$C$4,$A11+1,1),매입장!$B$4:$B$1503,기본설정!$C$6))-IF(기본설정!$C$6="전체",SUMPRODUCT((재고실사!$W$4:$W$403="주류·음료")*재고실사!$E$4:$E$403*INDEX(재고실사!$F$4:$R$403,0,$A11+1)),SUMPRODUCT((재고실사!$W$4:$W$403="주류·음료")*(재고실사!$A$4:$A$403=기본설정!$C$6)*재고실사!$E$4:$E$403*INDEX(재고실사!$F$4:$R$403,0,$A11+1))) -> 0 | K11: =IFERROR(J11/D11,0) -> 0 | L11: =IF(기본설정!$C$6="전체",SUMPRODUCT((재고실사!$W$4:$W$403="소모품")*재고실사!$E$4:$E$403*INDEX(재고실사!$F$4:$R$403,0,$A11+0)),SUMPRODUCT((재고실사!$W$4:$W$403="소모품")*(재고실사!$A$4:$A$403=기본설정!$C$6)*재고실사!$E$4:$E$403*INDEX(재고실사!$F$4:$R$403,0,$A11+0)))+IF(기본설정!$C$6="전체",SUMIFS(매입장!$I$4:$I$1503,매입장!$P$4:$P$1503,"소모품",매입장!$A$4:$A$1503,">="&DATE(기본설정!$C$4,$A11,1),매입장!$A$4:$A$1503,"<"&DATE(기본설정!$C$4,$A11+1,1)),SUMIFS(매입장!$I$4:$I$1503,매입장!$P$4:$P$1503,"소모품",매입장!$A$4:$A$1503,">="&DATE(기본설정!$C$4,$A11,1),매입장!$A$4:$A$1503,"<"&DATE(기본설정!$C$4,$A11+1,1),매입장!$B$4:$B$1503,기본설정!$C$6))-IF(기본설정!$C$6="전체",SUMPRODUCT((재고실사!$W$4:$W$403="소모품")*재고실사!$E$4:$E$403*INDEX(재고실사!$F$4:$R$403,0,$A11+1)),SUMPRODUCT((재고실사!$W$4:$W$403="소모품")*(재고실사!$A$4:$A$403=기본설정!$C$6)*재고실사!$E$4:$E$403*INDEX(재고실사!$F$4:$R$403,0,$A11+1))) -> 0 | M11: =G11+J11+L11 -> 0 | N11: =IFERROR(M11/E11,0) -> 0 | O11: =E11-M11 -> 0 | P11: =IFERROR(O11/E11,0) -> 0 | Q11: =IF(기본설정!$C$6="전체",SUMIFS(매출일보!$J$4:$J$403,매출일보!$A$4:$A$403,">="&DATE(기본설정!$C$4,$A11,1),매출일보!$A$4:$A$403,"<"&DATE(기본설정!$C$4,$A11+1,1)),SUMIFS(매출일보!$J$4:$J$403,매출일보!$A$4:$A$403,">="&DATE(기본설정!$C$4,$A11,1),매출일보!$A$4:$A$403,"<"&DATE(기본설정!$C$4,$A11+1,1),매출일보!$B$4:$B$403,기본설정!$C$6)) -> 0 | R11: =IFERROR(B11/Q11,0) -> 0 | S11: =IF(SUMPRODUCT(--(INDEX(재고실사!$F$4:$R$403,0,$A11+1)<>""))>0,"입력","미입력") -> 미입력
